Workbook

Sheet Cover
A1: Drive-thru — highway drive-thru: 5-year financial model
A3: Purpose: investment decision support for the first unit (recommended mid-range concept). All values AMD, nominal, excl. VAT unless stated.
A4: How to use: change blue cells on 'Inputs' (and 'Capex'); every other sheet recalculates. Concept switch: Inputs › concept_index.
A5: Evidence: every input carries a status tag and source; research files are in research/. Placeholders must be replaced by fieldwork (traffic counts, quotes).
A7: Scenario summary | C7: Conservative | D7: Base | E7: Optimistic
A8: Total investment (AMD) | C8: =Annual!C37 | D8: =Annual!C85 | E8: =Annual!C133
A9: Total investment (USD) | C9: =Annual!C38 | D9: =Annual!C86 | E9: =Annual!C134
A10: Year-1 net sales | C10: =Annual!C8 | D10: =Annual!C56 | E10: =Annual!C104
A11: Year-3 net sales | C11: =Annual!E8 | D11: =Annual!E56 | E11: =Annual!E104
A12: Year-1 transactions/day | C12: =Annual!C5 | D12: =Annual!C53 | E12: =Annual!C101
A13: Year-3 transactions/day | C13: =Annual!E5 | D13: =Annual!E53 | E13: =Annual!E101
A14: Year-1 EBITDA | C14: =Annual!C21 | D14: =Annual!C69 | E14: =Annual!C117
A15: Year-3 EBITDA | C15: =Annual!E21 | D15: =Annual!E69 | E15: =Annual!E117
A16: Year-3 EBITDA margin | C16: =Annual!E22 | D16: =Annual!E70 | E16: =Annual!E118
A17: Year-5 net income | C17: =Annual!G28 | D17: =Annual!G76 | E17: =Annual!G124
A18: Payback (months) | C18: =Annual!C39 | D18: =Annual!C87 | E18: =Annual!C135
A19: NPV (5 yrs + residual) | C19: =Annual!C41 | D19: =Annual!C89 | E19: =Annual!C137
A20: IRR (5 yrs + residual) | C20: =Annual!C42 | D20: =Annual!C90 | E20: =Annual!C138
A21: ROIC Year 3 | C21: =Annual!C44 | D21: =Annual!C92 | E21: =Annual!C140
A24: Colour legend: blue = input · black = formula · cream fill = editable assumption.
A25: Prepared 2026-10 as part of the investor package. Not investment advice; validate inputs with fieldwork before committing capital.

Sheet Inputs
A1: Drive-thru — model inputs
A2: Blue cells are inputs. Status: VERIFIED (primary source) · REPORTED (secondary) · ESTIMATE (derived) · ASSUMPTION (judgement). See research/ for evidence files.
A4: Key | B4: Input | C4: Unit | D4: Conservative | E4: Base | F4: Optimistic | G4: Status | H4: Source / basis
A6: General
A7: fx_amd_per_usd | B7: Exchange rate | C7: AMD/USD | D7: 385 | E7: 385 | F7: 385 | G7: ASSUMPTION | H7: PLACEHOLDER — replace with CBA rate
A8: opening_month | B8: Opening calendar month | C8: month | D8: 5 | E8: 5 | F8: 5 | G8: ASSUMPTION | H8: Open in May to catch first summer season
A9: open_days_per_year | B9: Trading days per year | C9: days | D9: 360 | E9: 360 | F9: 360 | G9: ASSUMPTION | H9: Closed ~5 days (New Year 1 Jan, Christmas 6 Jan, severe weather)
A10: vat_rate | B10: VAT | D10: 0.2 | E10: 0.2 | F10: 0.2 | G10: VERIFIED | H10: RA Tax Code art. 63
A11: profit_tax_rate | B11: Profit tax | D11: 0.18 | E11: 0.18 | F11: 0.18 | G11: VERIFIED | H11: RA Tax Code art. 115
A12: discount_rate | B12: Discount rate (AMD) | D12: 0.18 | E12: 0.18 | F12: 0.18 | G12: ASSUMPTION | H12: AMD equity hurdle: CBA policy rate ~6.75% + SME/country/start-up premium
A13: concept_index | B13: Concept modelled (1 = Lean, 2 = Mid-range, 3 = Flagship) | C13: index | D13: 2 | E13: 2 | F13: 2 | G13: ASSUMPTION | H13: Recommended: Mid-range
A14: land_mode_lease | B14: Land via ground lease? (1 = lease, 0 = buy) | C14: flag | D14: 1 | E14: 1 | F14: 1 | G14: ASSUMPTION | H14: Ground lease preferred for capital efficiency
A16: Demand
A17: traffic_aadt | B17: Passing traffic (AADT, two-way) | C17: veh/day two-way | D17: 12000 | E17: 16000 | F17: 20000 | G17: ASSUMPTION | H17: PLACEHOLDER
A18: traffic_growth | B18: Traffic growth | C18: /yr | D18: 0.01 | E18: 0.025 | F18: 0.04 | G18: ASSUMPTION | H18: Motorisation trend
A19: accessible_share | B19: Share of traffic that can access | D19: 0.5 | E19: 0.55 | F19: 0.6 | G19: ASSUMPTION | H19: Right-in/right-out from one carriageway + some U-turn capture
A20: capture_rate | B20: Capture rate of accessible vehicles (Y1 steady state) | D20: 0.012 | E20: 0.018 | F20: 0.025 | G20: ASSUMPTION | H20: PLACEHOLDER
A21: capture_growth | B21: Capture growth | C21: /yr | D21: 0.03 | E21: 0.06 | F21: 0.1 | G21: ASSUMPTION | H21: Brand awareness build Y2-Y5
A22: avg_ticket_amd | B22: Average transaction value (per order) | C22: AMD incl. VAT | D22: 2200 | E22: 2600 | F22: 3000 | G22: ASSUMPTION | H22: PLACEHOLDER
A23: other_transactions_day | B23: Non-highway transactions/day | C23: tx/day | D23: 10 | E23: 20 | F23: 30 | G23: ASSUMPTION | H23: Walk-in locals, staff of nearby businesses, pre-orders
A24: price_inflation | B24: Menu price growth | C24: /yr | D24: 0.03 | E24: 0.035 | F24: 0.04 | G24: ASSUMPTION | H24: CBA inflation target 4% ±1.5
A26: Seasonality index (traffic, mean = 1.00)
A27: season_1 | B27: Seasonality — Jan | C27: index | D27: 0.66 | E27: 0.66 | F27: 0.66 | G27: ESTIMATE | H27: PLACEHOLDER
A28: season_2 | B28: Seasonality — Feb | C28: index | D28: 0.68 | E28: 0.68 | F28: 0.68 | G28: ESTIMATE
A29: season_3 | B29: Seasonality — Mar | C29: index | D29: 0.8 | E29: 0.8 | F29: 0.8 | G29: ESTIMATE
A30: season_4 | B30: Seasonality — Apr | C30: index | D30: 0.92 | E30: 0.92 | F30: 0.92 | G30: ESTIMATE
A31: season_5 | B31: Seasonality — May | C31: index | D31: 1.02 | E31: 1.02 | F31: 1.02 | G31: ESTIMATE
A32: season_6 | B32: Seasonality — Jun | C32: index | D32: 1.2 | E32: 1.2 | F32: 1.2 | G32: ESTIMATE
A33: season_7 | B33: Seasonality — Jul | C33: index | D33: 1.42 | E33: 1.42 | F33: 1.42 | G33: ESTIMATE
A34: season_8 | B34: Seasonality — Aug | C34: index | D34: 1.46 | E34: 1.46 | F34: 1.46 | G34: ESTIMATE
A35: season_9 | B35: Seasonality — Sep | C35: index | D35: 1.14 | E35: 1.14 | F35: 1.14 | G35: ESTIMATE
A36: season_10 | B36: Seasonality — Oct | C36: index | D36: 0.96 | E36: 0.96 | F36: 0.96 | G36: ESTIMATE
A37: season_11 | B37: Seasonality — Nov | C37: index | D37: 0.82 | E37: 0.82 | F37: 0.82 | G37: ESTIMATE
A38: season_12 | B38: Seasonality — Dec | C38: index | D38: 0.92 | E38: 0.92 | F38: 0.92 | G38: ESTIMATE
A40: Opening ramp (capture multiplier by month since opening)
A41: ramp_1 | B41: Ramp — month 1 | C41: x | D41: 0.45 | E41: 0.55 | F41: 0.65 | G41: ASSUMPTION | H41: Typical new-unit ramp
A42: ramp_2 | B42: Ramp — month 2 | C42: x | D42: 0.55 | E42: 0.65 | F42: 0.75 | G42: ASSUMPTION
A43: ramp_3 | B43: Ramp — month 3 | C43: x | D43: 0.65 | E43: 0.74 | F43: 0.83 | G43: ASSUMPTION
A44: ramp_4 | B44: Ramp — month 4 | C44: x | D44: 0.72 | E44: 0.81 | F44: 0.89 | G44: ASSUMPTION
A45: ramp_5 | B45: Ramp — month 5 | C45: x | D45: 0.78 | E45: 0.86 | F45: 0.93 | G45: ASSUMPTION
...

Sheet Annual
A1: Drive-thru — 5-year P&L and cash flow (AMD, nominal)
A3: CONSERVATIVE SCENARIO | C3: Year 1 | D3: Year 2 | E3: Year 3 | F3: Year 4 | G3: Year 5
A4: Transactions (year) | C4: =SUMPRODUCT((M_Cons!$C$4:$BJ$4=1)*M_Cons!$C$11:$BJ$11*M_Cons!$C$6:$BJ$6) | D4: =SUMPRODUCT((M_Cons!$C$4:$BJ$4=2)*M_Cons!$C$11:$BJ$11*M_Cons!$C$6:$BJ$6) | E4: =SUMPRODUCT((M_Cons!$C$4:$BJ$4=3)*M_Cons!$C$11:$BJ$11*M_Cons!$C$6:$BJ$6) | F4: =SUMPRODUCT((M_Cons!$C$4:$BJ$4=4)*M_Cons!$C$11:$BJ$11*M_Cons!$C$6:$BJ$6) | G4: =SUMPRODUCT((M_Cons!$C$4:$BJ$4=5)*M_Cons!$C$11:$BJ$11*M_Cons!$C$6:$BJ$6)
A5: Transactions / day (avg) | C5: =C4/SUMIF(M_Cons!$C$4:$BJ$4,1,M_Cons!$C$6:$BJ$6) | D5: =D4/SUMIF(M_Cons!$C$4:$BJ$4,2,M_Cons!$C$6:$BJ$6) | E5: =E4/SUMIF(M_Cons!$C$4:$BJ$4,3,M_Cons!$C$6:$BJ$6) | F5: =F4/SUMIF(M_Cons!$C$4:$BJ$4,4,M_Cons!$C$6:$BJ$6) | G5: =G4/SUMIF(M_Cons!$C$4:$BJ$4,5,M_Cons!$C$6:$BJ$6)
A6: Average ticket (AMD incl. VAT) | C6: =C7/C4 | D6: =D7/D4 | E6: =E7/E4 | F6: =F7/F4 | G6: =G7/G4
A7: Gross sales (incl. VAT) | C7: =SUMIF(M_Cons!$C$4:$BJ$4,1,M_Cons!$C$13:$BJ$13) | D7: =SUMIF(M_Cons!$C$4:$BJ$4,2,M_Cons!$C$13:$BJ$13) | E7: =SUMIF(M_Cons!$C$4:$BJ$4,3,M_Cons!$C$13:$BJ$13) | F7: =SUMIF(M_Cons!$C$4:$BJ$4,4,M_Cons!$C$13:$BJ$13) | G7: =SUMIF(M_Cons!$C$4:$BJ$4,5,M_Cons!$C$13:$BJ$13)
A8: Net sales (excl. VAT) | C8: =SUMIF(M_Cons!$C$4:$BJ$4,1,M_Cons!$C$14:$BJ$14) | D8: =SUMIF(M_Cons!$C$4:$BJ$4,2,M_Cons!$C$14:$BJ$14) | E8: =SUMIF(M_Cons!$C$4:$BJ$4,3,M_Cons!$C$14:$BJ$14) | F8: =SUMIF(M_Cons!$C$4:$BJ$4,4,M_Cons!$C$14:$BJ$14) | G8: =SUMIF(M_Cons!$C$4:$BJ$4,5,M_Cons!$C$14:$BJ$14)
A9: COGS + waste | C9: =SUMIF(M_Cons!$C$4:$BJ$4,1,M_Cons!$C$15:$BJ$15) | D9: =SUMIF(M_Cons!$C$4:$BJ$4,2,M_Cons!$C$15:$BJ$15) | E9: =SUMIF(M_Cons!$C$4:$BJ$4,3,M_Cons!$C$15:$BJ$15) | F9: =SUMIF(M_Cons!$C$4:$BJ$4,4,M_Cons!$C$15:$BJ$15) | G9: =SUMIF(M_Cons!$C$4:$BJ$4,5,M_Cons!$C$15:$BJ$15)
A10: Gross profit | C10: =C8-C9 | D10: =D8-D9 | E10: =E8-E9 | F10: =F8-F9 | G10: =G8-G9
A11: Gross margin % | C11: =IFERROR(C10/C8,0) | D11: =IFERROR(D10/D8,0) | E11: =IFERROR(E10/E8,0) | F11: =IFERROR(F10/F8,0) | G11: =IFERROR(G10/G8,0)
A12: Labour | C12: =SUMIF(M_Cons!$C$4:$BJ$4,1,M_Cons!$C$23:$BJ$23) | D12: =SUMIF(M_Cons!$C$4:$BJ$4,2,M_Cons!$C$23:$BJ$23) | E12: =SUMIF(M_Cons!$C$4:$BJ$4,3,M_Cons!$C$23:$BJ$23) | F12: =SUMIF(M_Cons!$C$4:$BJ$4,4,M_Cons!$C$23:$BJ$23) | G12: =SUMIF(M_Cons!$C$4:$BJ$4,5,M_Cons!$C$23:$BJ$23)
A13: Ground rent | C13: =SUMIF(M_Cons!$C$4:$BJ$4,1,M_Cons!$C$24:$BJ$24) | D13: =SUMIF(M_Cons!$C$4:$BJ$4,2,M_Cons!$C$24:$BJ$24) | E13: =SUMIF(M_Cons!$C$4:$BJ$4,3,M_Cons!$C$24:$BJ$24) | F13: =SUMIF(M_Cons!$C$4:$BJ$4,4,M_Cons!$C$24:$BJ$24) | G13: =SUMIF(M_Cons!$C$4:$BJ$4,5,M_Cons!$C$24:$BJ$24)
A14: Utilities | C14: =SUMIF(M_Cons!$C$4:$BJ$4,1,M_Cons!$C$20:$BJ$20) | D14: =SUMIF(M_Cons!$C$4:$BJ$4,2,M_Cons!$C$20:$BJ$20) | E14: =SUMIF(M_Cons!$C$4:$BJ$4,3,M_Cons!$C$20:$BJ$20) | F14: =SUMIF(M_Cons!$C$4:$BJ$4,4,M_Cons!$C$20:$BJ$20) | G14: =SUMIF(M_Cons!$C$4:$BJ$4,5,M_Cons!$C$20:$BJ$20)
A15: Card fees | C15: =SUMIF(M_Cons!$C$4:$BJ$4,1,M_Cons!$C$16:$BJ$16) | D15: =SUMIF(M_Cons!$C$4:$BJ$4,2,M_Cons!$C$16:$BJ$16) | E15: =SUMIF(M_Cons!$C$4:$BJ$4,3,M_Cons!$C$16:$BJ$16) | F15: =SUMIF(M_Cons!$C$4:$BJ$4,4,M_Cons!$C$16:$BJ$16) | G15: =SUMIF(M_Cons!$C$4:$BJ$4,5,M_Cons!$C$16:$BJ$16)
A16: Marketing | C16: =SUMIF(M_Cons!$C$4:$BJ$4,1,M_Cons!$C$17:$BJ$17) | D16: =SUMIF(M_Cons!$C$4:$BJ$4,2,M_Cons!$C$17:$BJ$17) | E16: =SUMIF(M_Cons!$C$4:$BJ$4,3,M_Cons!$C$17:$BJ$17) | F16: =SUMIF(M_Cons!$C$4:$BJ$4,4,M_Cons!$C$17:$BJ$17) | G16: =SUMIF(M_Cons!$C$4:$BJ$4,5,M_Cons!$C$17:$BJ$17)
A17: Repairs & maintenance | C17: =SUMIF(M_Cons!$C$4:$BJ$4,1,M_Cons!$C$18:$BJ$18) | D17: =SUMIF(M_Cons!$C$4:$BJ$4,2,M_Cons!$C$18:$BJ$18) | E17: =SUMIF(M_Cons!$C$4:$BJ$4,3,M_Cons!$C$18:$BJ$18) | F17: =SUMIF(M_Cons!$C$4:$BJ$4,4,M_Cons!$C$18:$BJ$18) | G17: =SUMIF(M_Cons!$C$4:$BJ$4,5,M_Cons!$C$18:$BJ$18)
A18: Other variable | C18: =SUMIF(M_Cons!$C$4:$BJ$4,1,M_Cons!$C$19:$BJ$19) | D18: =SUMIF(M_Cons!$C$4:$BJ$4,2,M_Cons!$C$19:$BJ$19) | E18: =SUMIF(M_Cons!$C$4:$BJ$4,3,M_Cons!$C$19:$BJ$19) | F18: =SUMIF(M_Cons!$C$4:$BJ$4,4,M_Cons!$C$19:$BJ$19) | G18: =SUMIF(M_Cons!$C$4:$BJ$4,5,M_Cons!$C$19:$BJ$19)
A19: Other fixed + land tax | C19: =SUMIF(M_Cons!$C$4:$BJ$4,1,M_Cons!$C$25:$BJ$25) | D19: =SUMIF(M_Cons!$C$4:$BJ$4,2,M_Cons!$C$25:$BJ$25) | E19: =SUMIF(M_Cons!$C$4:$BJ$4,3,M_Cons!$C$25:$BJ$25) | F19: =SUMIF(M_Cons!$C$4:$BJ$4,4,M_Cons!$C$25:$BJ$25) | G19: =SUMIF(M_Cons!$C$4:$BJ$4,5,M_Cons!$C$25:$BJ$25)
A20: Total operating costs | C20: =SUMIF(M_Cons!$C$4:$BJ$4,1,M_Cons!$C$26:$BJ$26) | D20: =SUMIF(M_Cons!$C$4:$BJ$4,2,M_Cons!$C$26:$BJ$26) | E20: =SUMIF(M_Cons!$C$4:$BJ$4,3,M_Cons!$C$26:$BJ$26) | F20: =SUMIF(M_Cons!$C$4:$BJ$4,4,M_Cons!$C$26:$BJ$26) | G20: =SUMIF(M_Cons!$C$4:$BJ$4,5,M_Cons!$C$26:$BJ$26)
A21: EBITDA | C21: =SUMIF(M_Cons!$C$4:$BJ$4,1,M_Cons!$C$27:$BJ$27) | D21: =SUMIF(M_Cons!$C$4:$BJ$4,2,M_Cons!$C$27:$BJ$27) | E21: =SUMIF(M_Cons!$C$4:$BJ$4,3,M_Cons!$C$27:$BJ$27) | F21: =SUMIF(M_Cons!$C$4:$BJ$4,4,M_Cons!$C$27:$BJ$27) | G21: =SUMIF(M_Cons!$C$4:$BJ$4,5,M_Cons!$C$27:$BJ$27)
A22: EBITDA margin % | C22: =IFERROR(C21/C8,0) | D22: =IFERROR(D21/D8,0) | E22: =IFERROR(E21/E8,0) | F22: =IFERROR(F21/F8,0) | G22: =IFERROR(G21/G8,0)
A23: Depreciation | C23: =SUMIF(M_Cons!$C$4:$BJ$4,1,M_Cons!$C$28:$BJ$28) | D23: =SUMIF(M_Cons!$C$4:$BJ$4,2,M_Cons!$C$28:$BJ$28) | E23: =SUMIF(M_Cons!$C$4:$BJ$4,3,M_Cons!$C$28:$BJ$28) | F23: =SUMIF(M_Cons!$C$4:$BJ$4,4,M_Cons!$C$28:$BJ$28) | G23: =SUMIF(M_Cons!$C$4:$BJ$4,5,M_Cons!$C$28:$BJ$28)
A24: EBIT | C24: =SUMIF(M_Cons!$C$4:$BJ$4,1,M_Cons!$C$29:$BJ$29) | D24: =SUMIF(M_Cons!$C$4:$BJ$4,2,M_Cons!$C$29:$BJ$29) | E24: =SUMIF(M_Cons!$C$4:$BJ$4,3,M_Cons!$C$29:$BJ$29) | F24: =SUMIF(M_Cons!$C$4:$BJ$4,4,M_Cons!$C$29:$BJ$29) | G24: =SUMIF(M_Cons!$C$4:$BJ$4,5,M_Cons!$C$29:$BJ$29)
A25: Loss carried forward (opening) | C25: =0 | D25: =MAX(0,C25-C24) | E25: =MAX(0,D25-D24) | F25: =MAX(0,E25-E24) | G25: =MAX(0,F25-F24)
A26: Taxable profit | C26: =MAX(0,C24-C25) | D26: =MAX(0,D24-D25) | E26: =MAX(0,E24-E25) | F26: =MAX(0,F24-F25) | G26: =MAX(0,G24-G25)
A27: Profit tax | C27: =C26*Inputs!$D$11 | D27: =D26*Inputs!$D$11 | E27: =E26*Inputs!$D$11 | F27: =F26*Inputs!$D$11 | G27: =G26*Inputs!$D$11
A28: Net income | C28: =C24-C27 | D28: =D24-D27 | E28: =E24-E27 | F28: =F24-F27 | G28: =G24-G27
A29: Net margin % | C29: =IFERROR(C28/C8,0) | D29: =IFERROR(D28/D8,0) | E29: =IFERROR(E28/E8,0) | F29: =IFERROR(F28/F8,0) | G29: =IFERROR(G28/G8,0)
A30: Maintenance capex | C30: =0 | D30: =D8*Inputs!$D$72 | E30: =E8*Inputs!$D$72 | F30: =F8*Inputs!$D$72 | G30: =G8*Inputs!$D$72
A31: Working capital (closing) | C31: =C9*Inputs!$D$73/365 | D31: =D9*Inputs!$D$73/365 | E31: =E9*Inputs!$D$73/365 | F31: =F9*Inputs!$D$73/365 | G31: =G9*Inputs!$D$73/365
A32: Δ Working capital | C32: =C31 | D32: =D31-C31 | E32: =E31-D31 | F32: =F31-E31 | G32: =G31-F31
A33: Operating cash flow | C33: =C21-C27-C32 | D33: =D21-D27-D32 | E33: =E21-E27-E32 | F33: =F21-F27-F32 | G33: =G21-G27-G32
A34: Free cash flow | C34: =C33-C30 | D34: =D33-D30 | E34: =E33-E30 | F34: =F33-F30 | G34: =G33-G30
A35: Cumulative FCF after investment | C35: =-INDEX(Capex!$C$15:$E$15,1,Inputs!$E$13)+C34 | D35: =C35+D34 | E35: =D35+E34 | F35: =E35+F34 | G35: =F35+G34
A37: Total investment (capex + pre-opening) | C37: =INDEX(Capex!$C$15:$E$15,1,Inputs!$E$13)
A38: Total investment (USD) | C38: =INDEX(Capex!$C$15:$E$15,1,Inputs!$E$13)/Inputs!$D$7
A39: Payback (months from opening) | C39: =IF(MIN(M_Cons!$C$32:$BJ$32)>60,"> 60",MIN(M_Cons!$C$32:$BJ$32))
A40: Residual value end-Y5 (book value of fixed assets) | C40: =INDEX(Capex!$C$19:$E$19,1,Inputs!$E$13)*MAX(0,1-5/MAX(Inputs!$E$84,0.0001))*(Inputs!$E$84>0)+INDEX(Capex!$C$20:$E$20,1,Inputs!$E$13)*MAX(0,1-5/MAX(Inputs!$E$85,0.0001))*(Inputs!$E$85>0)+INDEX(Capex!$C$21:$E$21,1,Inputs!$E$13)*MAX(0,1-5/MAX(Inputs!$E$86,0.0001))*(Inputs!$E$86>0)+INDEX(Capex!$C$22:$E$22,1,Inputs!$E$13)*MAX(0,1-5/MAX(Inputs!$E$87,0.0001))*(Inputs!$E$87>0)+INDEX(Capex!$C$23:$E$23,1,Inputs!$E$13)*MAX(0,1-5/MAX(Inputs!$E$88,0.0001))*(Inputs!$E$88>0)+INDEX(Capex!$C$24:$E$24,1,Inputs!$E$13)*MAX(0,1-5/MAX(Inputs!$E$89,0.0001))*(Inputs!$E$89>0)+INDEX(Capex!$C$25:$E$25,1,Inputs!$E$13)*MAX(0,1-5/MAX(Inputs!$E$90,0.0001))*(Inputs!$E$90>0)
A41: NPV @ discount rate (5 yrs + residual) | C41: =C47+NPV(Inputs!$D$12,D47:H47)
A42: IRR (5 yrs + residual) | C42: =IFERROR(IRR(C47:H47),"n/a")
...

Sheet BreakEven
A1: Drive-thru — break-even and required traffic (Year-2 cost base)
A3: Metric | C3: Conservative | D3: Base | E3: Optimistic
A4: Year-2 net sales | C4: =Annual!D8 | D4: =Annual!D56 | E4: =Annual!D104
A5: Variable costs as % of net sales | C5: =(Annual!D9+Annual!D15+Annual!D17+Annual!D18+Annual!D16)/Annual!D8+Inputs!$D$63 | D5: =(Annual!D57+Annual!D63+Annual!D65+Annual!D66+Annual!D64)/Annual!D56+Inputs!$E$63 | E5: =(Annual!D105+Annual!D111+Annual!D113+Annual!D114+Annual!D112)/Annual!D104+Inputs!$F$63
A6: Fixed costs per year (labour, rent, fixed, utilities fixed) | C6: =Annual!D12+Annual!D13+Annual!D19+Annual!D14-Annual!D8*Inputs!$D$63 | D6: =Annual!D60+Annual!D61+Annual!D67+Annual!D62-Annual!D56*Inputs!$E$63 | E6: =Annual!D108+Annual!D109+Annual!D115+Annual!D110-Annual!D104*Inputs!$F$63
A7: Net ticket (excl. VAT) | C7: =Annual!D6/(1+Inputs!$D$10) | D7: =Annual!D54/(1+Inputs!$E$10) | E7: =Annual!D102/(1+Inputs!$F$10)
A8: Contribution per transaction | C8: =C7*(1-C5) | D8: =D7*(1-D5) | E8: =E7*(1-E5)
A9: Break-even transactions/day (EBITDA = 0) | C9: =C6/C8/Inputs!$D$9 | D9: =D6/D8/Inputs!$E$9 | E9: =E6/E8/Inputs!$F$9
A10: Break-even transactions/day (EBIT = 0) | C10: =(C6+Annual!D23)/C8/Inputs!$D$9 | D10: =(D6+Annual!D71)/D8/Inputs!$E$9 | E10: =(E6+Annual!D119)/E8/Inputs!$F$9
A11: Capture used (Y2) | C11: =Inputs!$D$20*(1+Inputs!$D$21) | D11: =Inputs!$E$20*(1+Inputs!$E$21) | E11: =Inputs!$F$20*(1+Inputs!$F$21)
A12: Accessible share used | C12: =Inputs!$D$19 | D12: =Inputs!$E$19 | E12: =Inputs!$F$19
A13: Non-highway transactions/day | C13: =Inputs!$D$23 | D13: =Inputs!$E$23 | E13: =Inputs!$F$23
A14: Break-even passing vehicles/day (two-way) | C14: =MAX(0,C9-C13)/(C12*C11) | D14: =MAX(0,D9-D13)/(D12*D11) | E14: =MAX(0,E9-E13)/(E12*E11)
A15: Transactions/day for 4-year cash payback | C15: =(C6+INDEX(Capex!$C$15:$E$15,1,Inputs!$E$13)/4/(1-0.18*0.6))/C8/Inputs!$D$9 | D15: =(D6+INDEX(Capex!$C$15:$E$15,1,Inputs!$E$13)/4/(1-0.18*0.6))/D8/Inputs!$E$9 | E15: =(E6+INDEX(Capex!$C$15:$E$15,1,Inputs!$E$13)/4/(1-0.18*0.6))/E8/Inputs!$F$9
A16: Passing vehicles/day for 4-year payback | C16: =MAX(0,C15-C13)/(C12*C11) | D16: =MAX(0,D15-D13)/(D12*D11) | E16: =MAX(0,E15-E13)/(E12*E11)
A17: Modelled Year-2 transactions/day | C17: =Annual!D5 | D17: =Annual!D53 | E17: =Annual!D101
A18: Safety margin vs EBITDA break-even | C18: =C17/C9-1 | D18: =D17/D9-1 | E18: =E17/E9-1
A21: Passing vehicles/day (two-way) needed for EBITDA break-even — BASE cost structure
A22: Rows: capture rate of accessible traffic · Columns: average ticket (AMD incl. VAT, Year-1 prices)
B23: capture \ ticket | C23: 1500 | D23: 1800 | E23: 2100 | F23: 2400 | G23: 2700 | H23: 3000 | I23: 3300 | J23: 3600 | K23: 4000
B24: 0.008 | C24: =MAX(0,($D$6/(C$23*(1+Inputs!$E$24)/(1+Inputs!$E$10)*(1-$D$5))/Inputs!$E$9)-Inputs!$E$23)/(Inputs!$E$19*$B24) | D24: =MAX(0,($D$6/(D$23*(1+Inputs!$E$24)/(1+Inputs!$E$10)*(1-$D$5))/Inputs!$E$9)-Inputs!$E$23)/(Inputs!$E$19*$B24) | E24: =MAX(0,($D$6/(E$23*(1+Inputs!$E$24)/(1+Inputs!$E$10)*(1-$D$5))/Inputs!$E$9)-Inputs!$E$23)/(Inputs!$E$19*$B24) | F24: =MAX(0,($D$6/(F$23*(1+Inputs!$E$24)/(1+Inputs!$E$10)*(1-$D$5))/Inputs!$E$9)-Inputs!$E$23)/(Inputs!$E$19*$B24) | G24: =MAX(0,($D$6/(G$23*(1+Inputs!$E$24)/(1+Inputs!$E$10)*(1-$D$5))/Inputs!$E$9)-Inputs!$E$23)/(Inputs!$E$19*$B24) | H24: =MAX(0,($D$6/(H$23*(1+Inputs!$E$24)/(1+Inputs!$E$10)*(1-$D$5))/Inputs!$E$9)-Inputs!$E$23)/(Inputs!$E$19*$B24) | I24: =MAX(0,($D$6/(I$23*(1+Inputs!$E$24)/(1+Inputs!$E$10)*(1-$D$5))/Inputs!$E$9)-Inputs!$E$23)/(Inputs!$E$19*$B24) | J24: =MAX(0,($D$6/(J$23*(1+Inputs!$E$24)/(1+Inputs!$E$10)*(1-$D$5))/Inputs!$E$9)-Inputs!$E$23)/(Inputs!$E$19*$B24) | K24: =MAX(0,($D$6/(K$23*(1+Inputs!$E$24)/(1+Inputs!$E$10)*(1-$D$5))/Inputs!$E$9)-Inputs!$E$23)/(Inputs!$E$19*$B24)
B25: 0.01 | C25: =MAX(0,($D$6/(C$23*(1+Inputs!$E$24)/(1+Inputs!$E$10)*(1-$D$5))/Inputs!$E$9)-Inputs!$E$23)/(Inputs!$E$19*$B25) | D25: =MAX(0,($D$6/(D$23*(1+Inputs!$E$24)/(1+Inputs!$E$10)*(1-$D$5))/Inputs!$E$9)-Inputs!$E$23)/(Inputs!$E$19*$B25) | E25: =MAX(0,($D$6/(E$23*(1+Inputs!$E$24)/(1+Inputs!$E$10)*(1-$D$5))/Inputs!$E$9)-Inputs!$E$23)/(Inputs!$E$19*$B25) | F25: =MAX(0,($D$6/(F$23*(1+Inputs!$E$24)/(1+Inputs!$E$10)*(1-$D$5))/Inputs!$E$9)-Inputs!$E$23)/(Inputs!$E$19*$B25) | G25: =MAX(0,($D$6/(G$23*(1+Inputs!$E$24)/(1+Inputs!$E$10)*(1-$D$5))/Inputs!$E$9)-Inputs!$E$23)/(Inputs!$E$19*$B25) | H25: =MAX(0,($D$6/(H$23*(1+Inputs!$E$24)/(1+Inputs!$E$10)*(1-$D$5))/Inputs!$E$9)-Inputs!$E$23)/(Inputs!$E$19*$B25) | I25: =MAX(0,($D$6/(I$23*(1+Inputs!$E$24)/(1+Inputs!$E$10)*(1-$D$5))/Inputs!$E$9)-Inputs!$E$23)/(Inputs!$E$19*$B25) | J25: =MAX(0,($D$6/(J$23*(1+Inputs!$E$24)/(1+Inputs!$E$10)*(1-$D$5))/Inputs!$E$9)-Inputs!$E$23)/(Inputs!$E$19*$B25) | K25: =MAX(0,($D$6/(K$23*(1+Inputs!$E$24)/(1+Inputs!$E$10)*(1-$D$5))/Inputs!$E$9)-Inputs!$E$23)/(Inputs!$E$19*$B25)
B26: 0.012 | C26: =MAX(0,($D$6/(C$23*(1+Inputs!$E$24)/(1+Inputs!$E$10)*(1-$D$5))/Inputs!$E$9)-Inputs!$E$23)/(Inputs!$E$19*$B26) | D26: =MAX(0,($D$6/(D$23*(1+Inputs!$E$24)/(1+Inputs!$E$10)*(1-$D$5))/Inputs!$E$9)-Inputs!$E$23)/(Inputs!$E$19*$B26) | E26: =MAX(0,($D$6/(E$23*(1+Inputs!$E$24)/(1+Inputs!$E$10)*(1-$D$5))/Inputs!$E$9)-Inputs!$E$23)/(Inputs!$E$19*$B26) | F26: =MAX(0,($D$6/(F$23*(1+Inputs!$E$24)/(1+Inputs!$E$10)*(1-$D$5))/Inputs!$E$9)-Inputs!$E$23)/(Inputs!$E$19*$B26) | G26: =MAX(0,($D$6/(G$23*(1+Inputs!$E$24)/(1+Inputs!$E$10)*(1-$D$5))/Inputs!$E$9)-Inputs!$E$23)/(Inputs!$E$19*$B26) | H26: =MAX(0,($D$6/(H$23*(1+Inputs!$E$24)/(1+Inputs!$E$10)*(1-$D$5))/Inputs!$E$9)-Inputs!$E$23)/(Inputs!$E$19*$B26) | I26: =MAX(0,($D$6/(I$23*(1+Inputs!$E$24)/(1+Inputs!$E$10)*(1-$D$5))/Inputs!$E$9)-Inputs!$E$23)/(Inputs!$E$19*$B26) | J26: =MAX(0,($D$6/(J$23*(1+Inputs!$E$24)/(1+Inputs!$E$10)*(1-$D$5))/Inputs!$E$9)-Inputs!$E$23)/(Inputs!$E$19*$B26) | K26: =MAX(0,($D$6/(K$23*(1+Inputs!$E$24)/(1+Inputs!$E$10)*(1-$D$5))/Inputs!$E$9)-Inputs!$E$23)/(Inputs!$E$19*$B26)
B27: 0.015 | C27: =MAX(0,($D$6/(C$23*(1+Inputs!$E$24)/(1+Inputs!$E$10)*(1-$D$5))/Inputs!$E$9)-Inputs!$E$23)/(Inputs!$E$19*$B27) | D27: =MAX(0,($D$6/(D$23*(1+Inputs!$E$24)/(1+Inputs!$E$10)*(1-$D$5))/Inputs!$E$9)-Inputs!$E$23)/(Inputs!$E$19*$B27) | E27: =MAX(0,($D$6/(E$23*(1+Inputs!$E$24)/(1+Inputs!$E$10)*(1-$D$5))/Inputs!$E$9)-Inputs!$E$23)/(Inputs!$E$19*$B27) | F27: =MAX(0,($D$6/(F$23*(1+Inputs!$E$24)/(1+Inputs!$E$10)*(1-$D$5))/Inputs!$E$9)-Inputs!$E$23)/(Inputs!$E$19*$B27) | G27: =MAX(0,($D$6/(G$23*(1+Inputs!$E$24)/(1+Inputs!$E$10)*(1-$D$5))/Inputs!$E$9)-Inputs!$E$23)/(Inputs!$E$19*$B27) | H27: =MAX(0,($D$6/(H$23*(1+Inputs!$E$24)/(1+Inputs!$E$10)*(1-$D$5))/Inputs!$E$9)-Inputs!$E$23)/(Inputs!$E$19*$B27) | I27: =MAX(0,($D$6/(I$23*(1+Inputs!$E$24)/(1+Inputs!$E$10)*(1-$D$5))/Inputs!$E$9)-Inputs!$E$23)/(Inputs!$E$19*$B27) | J27: =MAX(0,($D$6/(J$23*(1+Inputs!$E$24)/(1+Inputs!$E$10)*(1-$D$5))/Inputs!$E$9)-Inputs!$E$23)/(Inputs!$E$19*$B27) | K27: =MAX(0,($D$6/(K$23*(1+Inputs!$E$24)/(1+Inputs!$E$10)*(1-$D$5))/Inputs!$E$9)-Inputs!$E$23)/(Inputs!$E$19*$B27)
B28: 0.018 | C28: =MAX(0,($D$6/(C$23*(1+Inputs!$E$24)/(1+Inputs!$E$10)*(1-$D$5))/Inputs!$E$9)-Inputs!$E$23)/(Inputs!$E$19*$B28) | D28: =MAX(0,($D$6/(D$23*(1+Inputs!$E$24)/(1+Inputs!$E$10)*(1-$D$5))/Inputs!$E$9)-Inputs!$E$23)/(Inputs!$E$19*$B28) | E28: =MAX(0,($D$6/(E$23*(1+Inputs!$E$24)/(1+Inputs!$E$10)*(1-$D$5))/Inputs!$E$9)-Inputs!$E$23)/(Inputs!$E$19*$B28) | F28: =MAX(0,($D$6/(F$23*(1+Inputs!$E$24)/(1+Inputs!$E$10)*(1-$D$5))/Inputs!$E$9)-Inputs!$E$23)/(Inputs!$E$19*$B28) | G28: =MAX(0,($D$6/(G$23*(1+Inputs!$E$24)/(1+Inputs!$E$10)*(1-$D$5))/Inputs!$E$9)-Inputs!$E$23)/(Inputs!$E$19*$B28) | H28: =MAX(0,($D$6/(H$23*(1+Inputs!$E$24)/(1+Inputs!$E$10)*(1-$D$5))/Inputs!$E$9)-Inputs!$E$23)/(Inputs!$E$19*$B28) | I28: =MAX(0,($D$6/(I$23*(1+Inputs!$E$24)/(1+Inputs!$E$10)*(1-$D$5))/Inputs!$E$9)-Inputs!$E$23)/(Inputs!$E$19*$B28) | J28: =MAX(0,($D$6/(J$23*(1+Inputs!$E$24)/(1+Inputs!$E$10)*(1-$D$5))/Inputs!$E$9)-Inputs!$E$23)/(Inputs!$E$19*$B28) | K28: =MAX(0,($D$6/(K$23*(1+Inputs!$E$24)/(1+Inputs!$E$10)*(1-$D$5))/Inputs!$E$9)-Inputs!$E$23)/(Inputs!$E$19*$B28)
B29: 0.022 | C29: =MAX(0,($D$6/(C$23*(1+Inputs!$E$24)/(1+Inputs!$E$10)*(1-$D$5))/Inputs!$E$9)-Inputs!$E$23)/(Inputs!$E$19*$B29) | D29: =MAX(0,($D$6/(D$23*(1+Inputs!$E$24)/(1+Inputs!$E$10)*(1-$D$5))/Inputs!$E$9)-Inputs!$E$23)/(Inputs!$E$19*$B29) | E29: =MAX(0,($D$6/(E$23*(1+Inputs!$E$24)/(1+Inputs!$E$10)*(1-$D$5))/Inputs!$E$9)-Inputs!$E$23)/(Inputs!$E$19*$B29) | F29: =MAX(0,($D$6/(F$23*(1+Inputs!$E$24)/(1+Inputs!$E$10)*(1-$D$5))/Inputs!$E$9)-Inputs!$E$23)/(Inputs!$E$19*$B29) | G29: =MAX(0,($D$6/(G$23*(1+Inputs!$E$24)/(1+Inputs!$E$10)*(1-$D$5))/Inputs!$E$9)-Inputs!$E$23)/(Inputs!$E$19*$B29) | H29: =MAX(0,($D$6/(H$23*(1+Inputs!$E$24)/(1+Inputs!$E$10)*(1-$D$5))/Inputs!$E$9)-Inputs!$E$23)/(Inputs!$E$19*$B29) | I29: =MAX(0,($D$6/(I$23*(1+Inputs!$E$24)/(1+Inputs!$E$10)*(1-$D$5))/Inputs!$E$9)-Inputs!$E$23)/(Inputs!$E$19*$B29) | J29: =MAX(0,($D$6/(J$23*(1+Inputs!$E$24)/(1+Inputs!$E$10)*(1-$D$5))/Inputs!$E$9)-Inputs!$E$23)/(Inputs!$E$19*$B29) | K29: =MAX(0,($D$6/(K$23*(1+Inputs!$E$24)/(1+Inputs!$E$10)*(1-$D$5))/Inputs!$E$9)-Inputs!$E$23)/(Inputs!$E$19*$B29)
B30: 0.026 | C30: =MAX(0,($D$6/(C$23*(1+Inputs!$E$24)/(1+Inputs!$E$10)*(1-$D$5))/Inputs!$E$9)-Inputs!$E$23)/(Inputs!$E$19*$B30) | D30: =MAX(0,($D$6/(D$23*(1+Inputs!$E$24)/(1+Inputs!$E$10)*(1-$D$5))/Inputs!$E$9)-Inputs!$E$23)/(Inputs!$E$19*$B30) | E30: =MAX(0,($D$6/(E$23*(1+Inputs!$E$24)/(1+Inputs!$E$10)*(1-$D$5))/Inputs!$E$9)-Inputs!$E$23)/(Inputs!$E$19*$B30) | F30: =MAX(0,($D$6/(F$23*(1+Inputs!$E$24)/(1+Inputs!$E$10)*(1-$D$5))/Inputs!$E$9)-Inputs!$E$23)/(Inputs!$E$19*$B30) | G30: =MAX(0,($D$6/(G$23*(1+Inputs!$E$24)/(1+Inputs!$E$10)*(1-$D$5))/Inputs!$E$9)-Inputs!$E$23)/(Inputs!$E$19*$B30) | H30: =MAX(0,($D$6/(H$23*(1+Inputs!$E$24)/(1+Inputs!$E$10)*(1-$D$5))/Inputs!$E$9)-Inputs!$E$23)/(Inputs!$E$19*$B30) | I30: =MAX(0,($D$6/(I$23*(1+Inputs!$E$24)/(1+Inputs!$E$10)*(1-$D$5))/Inputs!$E$9)-Inputs!$E$23)/(Inputs!$E$19*$B30) | J30: =MAX(0,($D$6/(J$23*(1+Inputs!$E$24)/(1+Inputs!$E$10)*(1-$D$5))/Inputs!$E$9)-Inputs!$E$23)/(Inputs!$E$19*$B30) | K30: =MAX(0,($D$6/(K$23*(1+Inputs!$E$24)/(1+Inputs!$E$10)*(1-$D$5))/Inputs!$E$9)-Inputs!$E$23)/(Inputs!$E$19*$B30)
B31: 0.03 | C31: =MAX(0,($D$6/(C$23*(1+Inputs!$E$24)/(1+Inputs!$E$10)*(1-$D$5))/Inputs!$E$9)-Inputs!$E$23)/(Inputs!$E$19*$B31) | D31: =MAX(0,($D$6/(D$23*(1+Inputs!$E$24)/(1+Inputs!$E$10)*(1-$D$5))/Inputs!$E$9)-Inputs!$E$23)/(Inputs!$E$19*$B31) | E31: =MAX(0,($D$6/(E$23*(1+Inputs!$E$24)/(1+Inputs!$E$10)*(1-$D$5))/Inputs!$E$9)-Inputs!$E$23)/(Inputs!$E$19*$B31) | F31: =MAX(0,($D$6/(F$23*(1+Inputs!$E$24)/(1+Inputs!$E$10)*(1-$D$5))/Inputs!$E$9)-Inputs!$E$23)/(Inputs!$E$19*$B31) | G31: =MAX(0,($D$6/(G$23*(1+Inputs!$E$24)/(1+Inputs!$E$10)*(1-$D$5))/Inputs!$E$9)-Inputs!$E$23)/(Inputs!$E$19*$B31) | H31: =MAX(0,($D$6/(H$23*(1+Inputs!$E$24)/(1+Inputs!$E$10)*(1-$D$5))/Inputs!$E$9)-Inputs!$E$23)/(Inputs!$E$19*$B31) | I31: =MAX(0,($D$6/(I$23*(1+Inputs!$E$24)/(1+Inputs!$E$10)*(1-$D$5))/Inputs!$E$9)-Inputs!$E$23)/(Inputs!$E$19*$B31) | J31: =MAX(0,($D$6/(J$23*(1+Inputs!$E$24)/(1+Inputs!$E$10)*(1-$D$5))/Inputs!$E$9)-Inputs!$E$23)/(Inputs!$E$19*$B31) | K31: =MAX(0,($D$6/(K$23*(1+Inputs!$E$24)/(1+Inputs!$E$10)*(1-$D$5))/Inputs!$E$9)-Inputs!$E$23)/(Inputs!$E$19*$B31)
B32: 0.035 | C32: =MAX(0,($D$6/(C$23*(1+Inputs!$E$24)/(1+Inputs!$E$10)*(1-$D$5))/Inputs!$E$9)-Inputs!$E$23)/(Inputs!$E$19*$B32) | D32: =MAX(0,($D$6/(D$23*(1+Inputs!$E$24)/(1+Inputs!$E$10)*(1-$D$5))/Inputs!$E$9)-Inputs!$E$23)/(Inputs!$E$19*$B32) | E32: =MAX(0,($D$6/(E$23*(1+Inputs!$E$24)/(1+Inputs!$E$10)*(1-$D$5))/Inputs!$E$9)-Inputs!$E$23)/(Inputs!$E$19*$B32) | F32: =MAX(0,($D$6/(F$23*(1+Inputs!$E$24)/(1+Inputs!$E$10)*(1-$D$5))/Inputs!$E$9)-Inputs!$E$23)/(Inputs!$E$19*$B32) | G32: =MAX(0,($D$6/(G$23*(1+Inputs!$E$24)/(1+Inputs!$E$10)*(1-$D$5))/Inputs!$E$9)-Inputs!$E$23)/(Inputs!$E$19*$B32) | H32: =MAX(0,($D$6/(H$23*(1+Inputs!$E$24)/(1+Inputs!$E$10)*(1-$D$5))/Inputs!$E$9)-Inputs!$E$23)/(Inputs!$E$19*$B32) | I32: =MAX(0,($D$6/(I$23*(1+Inputs!$E$24)/(1+Inputs!$E$10)*(1-$D$5))/Inputs!$E$9)-Inputs!$E$23)/(Inputs!$E$19*$B32) | J32: =MAX(0,($D$6/(J$23*(1+Inputs!$E$24)/(1+Inputs!$E$10)*(1-$D$5))/Inputs!$E$9)-Inputs!$E$23)/(Inputs!$E$19*$B32) | K32: =MAX(0,($D$6/(K$23*(1+Inputs!$E$24)/(1+Inputs!$E$10)*(1-$D$5))/Inputs!$E$9)-Inputs!$E$23)/(Inputs!$E$19*$B32)
B33: 0.04 | C33: =MAX(0,($D$6/(C$23*(1+Inputs!$E$24)/(1+Inputs!$E$10)*(1-$D$5))/Inputs!$E$9)-Inputs!$E$23)/(Inputs!$E$19*$B33) | D33: =MAX(0,($D$6/(D$23*(1+Inputs!$E$24)/(1+Inputs!$E$10)*(1-$D$5))/Inputs!$E$9)-Inputs!$E$23)/(Inputs!$E$19*$B33) | E33: =MAX(0,($D$6/(E$23*(1+Inputs!$E$24)/(1+Inputs!$E$10)*(1-$D$5))/Inputs!$E$9)-Inputs!$E$23)/(Inputs!$E$19*$B33) | F33: =MAX(0,($D$6/(F$23*(1+Inputs!$E$24)/(1+Inputs!$E$10)*(1-$D$5))/Inputs!$E$9)-Inputs!$E$23)/(Inputs!$E$19*$B33) | G33: =MAX(0,($D$6/(G$23*(1+Inputs!$E$24)/(1+Inputs!$E$10)*(1-$D$5))/Inputs!$E$9)-Inputs!$E$23)/(Inputs!$E$19*$B33) | H33: =MAX(0,($D$6/(H$23*(1+Inputs!$E$24)/(1+Inputs!$E$10)*(1-$D$5))/Inputs!$E$9)-Inputs!$E$23)/(Inputs!$E$19*$B33) | I33: =MAX(0,($D$6/(I$23*(1+Inputs!$E$24)/(1+Inputs!$E$10)*(1-$D$5))/Inputs!$E$9)-Inputs!$E$23)/(Inputs!$E$19*$B33) | J33: =MAX(0,($D$6/(J$23*(1+Inputs!$E$24)/(1+Inputs!$E$10)*(1-$D$5))/Inputs!$E$9)-Inputs!$E$23)/(Inputs!$E$19*$B33) | K33: =MAX(0,($D$6/(K$23*(1+Inputs!$E$24)/(1+Inputs!$E$10)*(1-$D$5))/Inputs!$E$9)-Inputs!$E$23)/(Inputs!$E$19*$B33)

Sheet Sensitivity
A1: Drive-thru — sensitivity of Year-3 EBITDA (base scenario)
A2: Tornado values are computed by model/engine.py (static, regenerate after changing inputs). Grid below is formula-driven.
A4: Driver (flexed) | B4: Low case EBITDA Y3 | C4: High case EBITDA Y3 | D4: Swing | E4: Base EBITDA Y3
A5: Capture rate ±30% | B5: -10940263 | C5: 44201050 | D5: =ABS(C5-B5) | E5: 16630393
A6: Passing traffic ±20% | B6: -1750044 | C6: 35010831 | D6: =ABS(C6-B6) | E6: 16630393
A7: Accessible share ±20% | B7: -1750044 | C7: 35010831 | D7: =ABS(C7-B7) | E7: 16630393
A8: Average ticket ±15% | B8: 1374153 | C8: 31886633 | D8: =ABS(C8-B8) | E8: 16630393
A9: Labour cost ±20% | B9: 26052325 | C9: 7208462 | D9: =ABS(C9-B9) | E9: 16630393
A10: Rent ±30% | B10: 22471033 | C10: 10789753 | D10: =ABS(C10-B10) | E10: 16630393
A11: COGS ±3 pp | B11: 21830202 | C11: 11430584 | D11: =ABS(C11-B11) | E11: 16630393
A12: Seasonality amplitude ±30% | B12: 17511034 | C12: 15749753 | D12: =ABS(C12-B12) | E12: 16630393

Sheet Capex
A1: Drive-thru — startup investment by concept (AMD, excl. VAT)
A2: Line items with status tags. USD at the Inputs exchange rate. Detailed build-ups in the report (Phase 6).
A4: Line item | B4: Depreciation class | C4: Lean | D4: Mid-range | E4: Flagship | F4: Status | G4: Source / basis
A5: Modular building | B5: building | C5: 40000000 | D5: 0 | E5: 0 | F5: ASSUMPTION | G5: PLACEHOLDER
A6: Site works | B6: site_works | C6: 30000000 | D6: 55000000 | E6: 75000000 | F6: ASSUMPTION | G6: PLACEHOLDER
A7: Equipment | B7: equipment | C7: 25000000 | D7: 40000000 | E7: 55000000 | F7: ASSUMPTION | G7: PLACEHOLDER
A8: Technology | B8: technology | C8: 4000000 | D8: 6000000 | E8: 9000000 | F8: ASSUMPTION | G8: PLACEHOLDER
A9: Signage | B9: signage | C9: 6000000 | D9: 12000000 | E9: 18000000 | F9: ASSUMPTION | G9: PLACEHOLDER
A10: Soft costs | B10: soft | C10: 8000000 | D10: 15000000 | E10: 22000000 | F10: ASSUMPTION | G10: PLACEHOLDER
A11: Contingency | B11: site_works | C11: 10000000 | D11: 20000000 | E11: 30000000 | F11: ASSUMPTION | G11: PLACEHOLDER
A12: Building | B12: building | C12: 0 | D12: 90000000 | E12: 150000000 | F12: ASSUMPTION | G12: PLACEHOLDER
A13: TOTAL CAPEX | C13: =SUM(C5:C12) | D13: =SUM(D5:D12) | E13: =SUM(E5:E12)
A14: Pre-opening costs (from Inputs) | C14: =Inputs!D81 | D14: =Inputs!E81 | E14: =Inputs!F81
A15: TOTAL INVESTMENT (capex + pre-opening) | C15: =C13+C14 | D15: =D13+D14 | E15: =E13+E14
A16: TOTAL INVESTMENT (USD) | C16: =C15/Inputs!$E$7 | D16: =D15/Inputs!$E$7 | E16: =E15/Inputs!$E$7
A18: Capex by depreciation class
A19: building | C19: =SUMIF($B$5:$B$12,"building",C$5:C$12) | D19: =SUMIF($B$5:$B$12,"building",D$5:D$12) | E19: =SUMIF($B$5:$B$12,"building",E$5:E$12)
A20: site_works | C20: =SUMIF($B$5:$B$12,"site_works",C$5:C$12) | D20: =SUMIF($B$5:$B$12,"site_works",D$5:D$12) | E20: =SUMIF($B$5:$B$12,"site_works",E$5:E$12)
A21: equipment | C21: =SUMIF($B$5:$B$12,"equipment",C$5:C$12) | D21: =SUMIF($B$5:$B$12,"equipment",D$5:D$12) | E21: =SUMIF($B$5:$B$12,"equipment",E$5:E$12)
A22: technology | C22: =SUMIF($B$5:$B$12,"technology",C$5:C$12) | D22: =SUMIF($B$5:$B$12,"technology",D$5:D$12) | E22: =SUMIF($B$5:$B$12,"technology",E$5:E$12)
A23: signage | C23: =SUMIF($B$5:$B$12,"signage",C$5:C$12) | D23: =SUMIF($B$5:$B$12,"signage",D$5:D$12) | E23: =SUMIF($B$5:$B$12,"signage",E$5:E$12)
A24: soft | C24: =SUMIF($B$5:$B$12,"soft",C$5:C$12) | D24: =SUMIF($B$5:$B$12,"soft",D$5:D$12) | E24: =SUMIF($B$5:$B$12,"soft",E$5:E$12)
A25: land | C25: =SUMIF($B$5:$B$12,"land",C$5:C$12) | D25: =SUMIF($B$5:$B$12,"land",D$5:D$12) | E25: =SUMIF($B$5:$B$12,"land",E$5:E$12)

Sheet M_Cons
A1: Drive-thru — monthly engine — CONSERVATIVE scenario (AMD)
B2: Units | C2: =CHOOSE(C5,"Jan","Feb","Mar","Apr","May","Jun","Jul","Aug","Sep","Oct","Nov","Dec")&" Y"&C4 | D2: =CHOOSE(D5,"Jan","Feb","Mar","Apr","May","Jun","Jul","Aug","Sep","Oct","Nov","Dec")&" Y"&D4 | E2: =CHOOSE(E5,"Jan","Feb","Mar","Apr","May","Jun","Jul","Aug","Sep","Oct","Nov","Dec")&" Y"&E4 | F2: =CHOOSE(F5,"Jan","Feb","Mar","Apr","May","Jun","Jul","Aug","Sep","Oct","Nov","Dec")&" Y"&F4 | G2: =CHOOSE(G5,"Jan","Feb","Mar","Apr","May","Jun","Jul","Aug","Sep","Oct","Nov","Dec")&" Y"&G4 | H2: =CHOOSE(H5,"Jan","Feb","Mar","Apr","May","Jun","Jul","Aug","Sep","Oct","Nov","Dec")&" Y"&H4 | I2: =CHOOSE(I5,"Jan","Feb","Mar","Apr","May","Jun","Jul","Aug","Sep","Oct","Nov","Dec")&" Y"&I4 | J2: =CHOOSE(J5,"Jan","Feb","Mar","Apr","May","Jun","Jul","Aug","Sep","Oct","Nov","Dec")&" Y"&J4 | ... BJ2: =CHOOSE(BJ5,"Jan","Feb","Mar","Apr","May","Jun","Jul","Aug","Sep","Oct","Nov","Dec")&" Y"&BJ4
A3: Month # | C3: 1 | D3: 2 | E3: 3 | F3: 4 | G3: 5 | H3: 6 | I3: 7 | J3: 8 | K3: 9 | L3: 10 | M3: 11 | N3: 12 | O3: 13 | P3: 14 | Q3: 15 | R3: 16 | S3: 17 | T3: 18 | U3: 19 | V3: 20 | W3: 21 | X3: 22 | Y3: 23 | Z3: 24 | AA3: 25 | AB3: 26 | AC3: 27 | AD3: 28 | AE3: 29 | AF3: 30 | AG3: 31 | AH3: 32 | AI3: 33 | AJ3: 34 | AK3: 35 | AL3: 36 | AM3: 37 | AN3: 38 | AO3: 39 | AP3: 40 | AQ3: 41 | AR3: 42 | AS3: 43 | AT3: 44 | AU3: 45 | AV3: 46 | AW3: 47 | AX3: 48 | AY3: 49 | AZ3: 50 | BA3: 51 | BB3: 52 | BC3: 53 | BD3: 54 | BE3: 55 | BF3: 56 | BG3: 57 | BH3: 58 | BI3: 59 | BJ3: 60
A4: Year | C4: =INT((C3-1)/12)+1 | D4: =INT((D3-1)/12)+1 | E4: =INT((E3-1)/12)+1 | F4: =INT((F3-1)/12)+1 | G4: =INT((G3-1)/12)+1 | H4: =INT((H3-1)/12)+1 | I4: =INT((I3-1)/12)+1 | J4: =INT((J3-1)/12)+1 | ... BJ4: =INT((BJ3-1)/12)+1
A5: Calendar month (1-12) | C5: =MOD(Inputs!$D$8-1+C3-1,12)+1 | D5: =MOD(Inputs!$D$8-1+D3-1,12)+1 | E5: =MOD(Inputs!$D$8-1+E3-1,12)+1 | F5: =MOD(Inputs!$D$8-1+F3-1,12)+1 | G5: =MOD(Inputs!$D$8-1+G3-1,12)+1 | H5: =MOD(Inputs!$D$8-1+H3-1,12)+1 | I5: =MOD(Inputs!$D$8-1+I3-1,12)+1 | J5: =MOD(Inputs!$D$8-1+J3-1,12)+1 | ... BJ5: =MOD(Inputs!$D$8-1+BJ3-1,12)+1
A6: Trading days | C6: =CHOOSE(C5,31,28,31,30,31,30,31,31,30,31,30,31)*Inputs!$D$9/365 | D6: =CHOOSE(D5,31,28,31,30,31,30,31,31,30,31,30,31)*Inputs!$D$9/365 | E6: =CHOOSE(E5,31,28,31,30,31,30,31,31,30,31,30,31)*Inputs!$D$9/365 | F6: =CHOOSE(F5,31,28,31,30,31,30,31,31,30,31,30,31)*Inputs!$D$9/365 | G6: =CHOOSE(G5,31,28,31,30,31,30,31,31,30,31,30,31)*Inputs!$D$9/365 | H6: =CHOOSE(H5,31,28,31,30,31,30,31,31,30,31,30,31)*Inputs!$D$9/365 | I6: =CHOOSE(I5,31,28,31,30,31,30,31,31,30,31,30,31)*Inputs!$D$9/365 | J6: =CHOOSE(J5,31,28,31,30,31,30,31,31,30,31,30,31)*Inputs!$D$9/365 | ... BJ6: =CHOOSE(BJ5,31,28,31,30,31,30,31,31,30,31,30,31)*Inputs!$D$9/365
A7: Seasonality index | C7: =INDEX(Inputs!$D$27:$D$38,C5) | D7: =INDEX(Inputs!$D$27:$D$38,D5) | E7: =INDEX(Inputs!$D$27:$D$38,E5) | F7: =INDEX(Inputs!$D$27:$D$38,F5) | G7: =INDEX(Inputs!$D$27:$D$38,G5) | H7: =INDEX(Inputs!$D$27:$D$38,H5) | I7: =INDEX(Inputs!$D$27:$D$38,I5) | J7: =INDEX(Inputs!$D$27:$D$38,J5) | ... BJ7: =INDEX(Inputs!$D$27:$D$38,BJ5)
A8: Passing traffic (veh/day) | C8: =Inputs!$D$17*(1+Inputs!$D$18)^(C4-1)*C7 | D8: =Inputs!$D$17*(1+Inputs!$D$18)^(D4-1)*D7 | E8: =Inputs!$D$17*(1+Inputs!$D$18)^(E4-1)*E7 | F8: =Inputs!$D$17*(1+Inputs!$D$18)^(F4-1)*F7 | G8: =Inputs!$D$17*(1+Inputs!$D$18)^(G4-1)*G7 | H8: =Inputs!$D$17*(1+Inputs!$D$18)^(H4-1)*H7 | I8: =Inputs!$D$17*(1+Inputs!$D$18)^(I4-1)*I7 | J8: =Inputs!$D$17*(1+Inputs!$D$18)^(J4-1)*J7 | ... BJ8: =Inputs!$D$17*(1+Inputs!$D$18)^(BJ4-1)*BJ7
A9: Ramp multiplier | C9: =IF(C3<=12,INDEX(Inputs!$D$41:$D$52,C3),1) | D9: =IF(D3<=12,INDEX(Inputs!$D$41:$D$52,D3),1) | E9: =IF(E3<=12,INDEX(Inputs!$D$41:$D$52,E3),1) | F9: =IF(F3<=12,INDEX(Inputs!$D$41:$D$52,F3),1) | G9: =IF(G3<=12,INDEX(Inputs!$D$41:$D$52,G3),1) | H9: =IF(H3<=12,INDEX(Inputs!$D$41:$D$52,H3),1) | I9: =IF(I3<=12,INDEX(Inputs!$D$41:$D$52,I3),1) | J9: =IF(J3<=12,INDEX(Inputs!$D$41:$D$52,J3),1) | ... BJ9: =IF(BJ3<=12,INDEX(Inputs!$D$41:$D$52,BJ3),1)
A10: Capture rate | C10: =Inputs!$D$20*(1+Inputs!$D$21)^(C4-1)*C9 | D10: =Inputs!$D$20*(1+Inputs!$D$21)^(D4-1)*D9 | E10: =Inputs!$D$20*(1+Inputs!$D$21)^(E4-1)*E9 | F10: =Inputs!$D$20*(1+Inputs!$D$21)^(F4-1)*F9 | G10: =Inputs!$D$20*(1+Inputs!$D$21)^(G4-1)*G9 | H10: =Inputs!$D$20*(1+Inputs!$D$21)^(H4-1)*H9 | I10: =Inputs!$D$20*(1+Inputs!$D$21)^(I4-1)*I9 | J10: =Inputs!$D$20*(1+Inputs!$D$21)^(J4-1)*J9 | ... BJ10: =Inputs!$D$20*(1+Inputs!$D$21)^(BJ4-1)*BJ9
A11: Transactions / day | C11: =C8*Inputs!$D$19*C10+Inputs!$D$23*C9 | D11: =D8*Inputs!$D$19*D10+Inputs!$D$23*D9 | E11: =E8*Inputs!$D$19*E10+Inputs!$D$23*E9 | F11: =F8*Inputs!$D$19*F10+Inputs!$D$23*F9 | G11: =G8*Inputs!$D$19*G10+Inputs!$D$23*G9 | H11: =H8*Inputs!$D$19*H10+Inputs!$D$23*H9 | I11: =I8*Inputs!$D$19*I10+Inputs!$D$23*I9 | J11: =J8*Inputs!$D$19*J10+Inputs!$D$23*J9 | ... BJ11: =BJ8*Inputs!$D$19*BJ10+Inputs!$D$23*BJ9
A12: Average ticket (AMD, incl. VAT) | C12: =Inputs!$D$22*(1+Inputs!$D$24)^(C4-1) | D12: =Inputs!$D$22*(1+Inputs!$D$24)^(D4-1) | E12: =Inputs!$D$22*(1+Inputs!$D$24)^(E4-1) | F12: =Inputs!$D$22*(1+Inputs!$D$24)^(F4-1) | G12: =Inputs!$D$22*(1+Inputs!$D$24)^(G4-1) | H12: =Inputs!$D$22*(1+Inputs!$D$24)^(H4-1) | I12: =Inputs!$D$22*(1+Inputs!$D$24)^(I4-1) | J12: =Inputs!$D$22*(1+Inputs!$D$24)^(J4-1) | ... BJ12: =Inputs!$D$22*(1+Inputs!$D$24)^(BJ4-1)
A13: Gross sales (incl. VAT) | C13: =C11*C6*C12 | D13: =D11*D6*D12 | E13: =E11*E6*E12 | F13: =F11*F6*F12 | G13: =G11*G6*G12 | H13: =H11*H6*H12 | I13: =I11*I6*I12 | J13: =J11*J6*J12 | ... BJ13: =BJ11*BJ6*BJ12
A14: Net sales (excl. VAT) | C14: =C13/(1+Inputs!$D$10) | D14: =D13/(1+Inputs!$D$10) | E14: =E13/(1+Inputs!$D$10) | F14: =F13/(1+Inputs!$D$10) | G14: =G13/(1+Inputs!$D$10) | H14: =H13/(1+Inputs!$D$10) | I14: =I13/(1+Inputs!$D$10) | J14: =J13/(1+Inputs!$D$10) | ... BJ14: =BJ13/(1+Inputs!$D$10)
A15: COGS + waste | C15: =C14*(Inputs!$D$55+Inputs!$D$56) | D15: =D14*(Inputs!$D$55+Inputs!$D$56) | E15: =E14*(Inputs!$D$55+Inputs!$D$56) | F15: =F14*(Inputs!$D$55+Inputs!$D$56) | G15: =G14*(Inputs!$D$55+Inputs!$D$56) | H15: =H14*(Inputs!$D$55+Inputs!$D$56) | I15: =I14*(Inputs!$D$55+Inputs!$D$56) | J15: =J14*(Inputs!$D$55+Inputs!$D$56) | ... BJ15: =BJ14*(Inputs!$D$55+Inputs!$D$56)
A16: Card fees | C16: =C13*Inputs!$D$57*Inputs!$D$58 | D16: =D13*Inputs!$D$57*Inputs!$D$58 | E16: =E13*Inputs!$D$57*Inputs!$D$58 | F16: =F13*Inputs!$D$57*Inputs!$D$58 | G16: =G13*Inputs!$D$57*Inputs!$D$58 | H16: =H13*Inputs!$D$57*Inputs!$D$58 | I16: =I13*Inputs!$D$57*Inputs!$D$58 | J16: =J13*Inputs!$D$57*Inputs!$D$58 | ... BJ16: =BJ13*Inputs!$D$57*Inputs!$D$58
A17: Marketing | C17: =C14*Inputs!$D$59+IF(C3<=3,Inputs!$D$60/3,0) | D17: =D14*Inputs!$D$59+IF(D3<=3,Inputs!$D$60/3,0) | E17: =E14*Inputs!$D$59+IF(E3<=3,Inputs!$D$60/3,0) | F17: =F14*Inputs!$D$59+IF(F3<=3,Inputs!$D$60/3,0) | G17: =G14*Inputs!$D$59+IF(G3<=3,Inputs!$D$60/3,0) | H17: =H14*Inputs!$D$59+IF(H3<=3,Inputs!$D$60/3,0) | I17: =I14*Inputs!$D$59+IF(I3<=3,Inputs!$D$60/3,0) | J17: =J14*Inputs!$D$59+IF(J3<=3,Inputs!$D$60/3,0) | ... BJ17: =BJ14*Inputs!$D$59+IF(BJ3<=3,Inputs!$D$60/3,0)
A18: Repairs & maintenance | C18: =C14*Inputs!$D$61 | D18: =D14*Inputs!$D$61 | E18: =E14*Inputs!$D$61 | F18: =F14*Inputs!$D$61 | G18: =G14*Inputs!$D$61 | H18: =H14*Inputs!$D$61 | I18: =I14*Inputs!$D$61 | J18: =J14*Inputs!$D$61 | ... BJ18: =BJ14*Inputs!$D$61
A19: Other variable | C19: =C14*Inputs!$D$62 | D19: =D14*Inputs!$D$62 | E19: =E14*Inputs!$D$62 | F19: =F14*Inputs!$D$62 | G19: =G14*Inputs!$D$62 | H19: =H14*Inputs!$D$62 | I19: =I14*Inputs!$D$62 | J19: =J14*Inputs!$D$62 | ... BJ19: =BJ14*Inputs!$D$62
A20: Utilities | C20: =INDEX(Inputs!$D$80:$F$80,1,Inputs!$E$13)*(1+Inputs!$D$70)^(C4-1)+C14*Inputs!$D$63 | D20: =INDEX(Inputs!$D$80:$F$80,1,Inputs!$E$13)*(1+Inputs!$D$70)^(D4-1)+D14*Inputs!$D$63 | E20: =INDEX(Inputs!$D$80:$F$80,1,Inputs!$E$13)*(1+Inputs!$D$70)^(E4-1)+E14*Inputs!$D$63 | F20: =INDEX(Inputs!$D$80:$F$80,1,Inputs!$E$13)*(1+Inputs!$D$70)^(F4-1)+F14*Inputs!$D$63 | G20: =INDEX(Inputs!$D$80:$F$80,1,Inputs!$E$13)*(1+Inputs!$D$70)^(G4-1)+G14*Inputs!$D$63 | H20: =INDEX(Inputs!$D$80:$F$80,1,Inputs!$E$13)*(1+Inputs!$D$70)^(H4-1)+H14*Inputs!$D$63 | I20: =INDEX(Inputs!$D$80:$F$80,1,Inputs!$E$13)*(1+Inputs!$D$70)^(I4-1)+I14*Inputs!$D$63 | J20: =INDEX(Inputs!$D$80:$F$80,1,Inputs!$E$13)*(1+Inputs!$D$70)^(J4-1)+J14*Inputs!$D$63 | ... BJ20: =INDEX(Inputs!$D$80:$F$80,1,Inputs!$E$13)*(1+Inputs!$D$70)^(BJ4-1)+BJ14*Inputs!$D$63
A21: Peak-season flag | C21: =IF(C7>=Inputs!$D$69,1,0) | D21: =IF(D7>=Inputs!$D$69,1,0) | E21: =IF(E7>=Inputs!$D$69,1,0) | F21: =IF(F7>=Inputs!$D$69,1,0) | G21: =IF(G7>=Inputs!$D$69,1,0) | H21: =IF(H7>=Inputs!$D$69,1,0) | I21: =IF(I7>=Inputs!$D$69,1,0) | J21: =IF(J7>=Inputs!$D$69,1,0) | ... BJ21: =IF(BJ7>=Inputs!$D$69,1,0)
A22: FTE | C22: =INDEX(Inputs!$D$76:$F$76,1,Inputs!$E$13)+C21*INDEX(Inputs!$D$77:$F$77,1,Inputs!$E$13) | D22: =INDEX(Inputs!$D$76:$F$76,1,Inputs!$E$13)+D21*INDEX(Inputs!$D$77:$F$77,1,Inputs!$E$13) | E22: =INDEX(Inputs!$D$76:$F$76,1,Inputs!$E$13)+E21*INDEX(Inputs!$D$77:$F$77,1,Inputs!$E$13) | F22: =INDEX(Inputs!$D$76:$F$76,1,Inputs!$E$13)+F21*INDEX(Inputs!$D$77:$F$77,1,Inputs!$E$13) | G22: =INDEX(Inputs!$D$76:$F$76,1,Inputs!$E$13)+G21*INDEX(Inputs!$D$77:$F$77,1,Inputs!$E$13) | H22: =INDEX(Inputs!$D$76:$F$76,1,Inputs!$E$13)+H21*INDEX(Inputs!$D$77:$F$77,1,Inputs!$E$13) | I22: =INDEX(Inputs!$D$76:$F$76,1,Inputs!$E$13)+I21*INDEX(Inputs!$D$77:$F$77,1,Inputs!$E$13) | J22: =INDEX(Inputs!$D$76:$F$76,1,Inputs!$E$13)+J21*INDEX(Inputs!$D$77:$F$77,1,Inputs!$E$13) | ... BJ22: =INDEX(Inputs!$D$76:$F$76,1,Inputs!$E$13)+BJ21*INDEX(Inputs!$D$77:$F$77,1,Inputs!$E$13)
A23: Labour | C23: =(C22*INDEX(Inputs!$D$78:$F$78,1,Inputs!$E$13)+INDEX(Inputs!$D$79:$F$79,1,Inputs!$E$13))*(1+Inputs!$D$71)^(C4-1)*(1+Inputs!$D$67)+C22*Inputs!$D$68 | D23: =(D22*INDEX(Inputs!$D$78:$F$78,1,Inputs!$E$13)+INDEX(Inputs!$D$79:$F$79,1,Inputs!$E$13))*(1+Inputs!$D$71)^(D4-1)*(1+Inputs!$D$67)+D22*Inputs!$D$68 | E23: =(E22*INDEX(Inputs!$D$78:$F$78,1,Inputs!$E$13)+INDEX(Inputs!$D$79:$F$79,1,Inputs!$E$13))*(1+Inputs!$D$71)^(E4-1)*(1+Inputs!$D$67)+E22*Inputs!$D$68 | F23: =(F22*INDEX(Inputs!$D$78:$F$78,1,Inputs!$E$13)+INDEX(Inputs!$D$79:$F$79,1,Inputs!$E$13))*(1+Inputs!$D$71)^(F4-1)*(1+Inputs!$D$67)+F22*Inputs!$D$68 | G23: =(G22*INDEX(Inputs!$D$78:$F$78,1,Inputs!$E$13)+INDEX(Inputs!$D$79:$F$79,1,Inputs!$E$13))*(1+Inputs!$D$71)^(G4-1)*(1+Inputs!$D$67)+G22*Inputs!$D$68 | H23: =(H22*INDEX(Inputs!$D$78:$F$78,1,Inputs!$E$13)+INDEX(Inputs!$D$79:$F$79,1,Inputs!$E$13))*(1+Inputs!$D$71)^(H4-1)*(1+Inputs!$D$67)+H22*Inputs!$D$68 | I23: =(I22*INDEX(Inputs!$D$78:$F$78,1,Inputs!$E$13)+INDEX(Inputs!$D$79:$F$79,1,Inputs!$E$13))*(1+Inputs!$D$71)^(I4-1)*(1+Inputs!$D$67)+I22*Inputs!$D$68 | J23: =(J22*INDEX(Inputs!$D$78:$F$78,1,Inputs!$E$13)+INDEX(Inputs!$D$79:$F$79,1,Inputs!$E$13))*(1+Inputs!$D$71)^(J4-1)*(1+Inputs!$D$67)+J22*Inputs!$D$68 | ... BJ23: =(BJ22*INDEX(Inputs!$D$78:$F$78,1,Inputs!$E$13)+INDEX(Inputs!$D$79:$F$79,1,Inputs!$E$13))*(1+Inputs!$D$71)^(BJ4-1)*(1+Inputs!$D$67)+BJ22*Inputs!$D$68
A24: Ground rent | C24: =Inputs!$D$14*Inputs!$D$65*(1+Inputs!$D$70)^(C4-1) | D24: =Inputs!$D$14*Inputs!$D$65*(1+Inputs!$D$70)^(D4-1) | E24: =Inputs!$D$14*Inputs!$D$65*(1+Inputs!$D$70)^(E4-1) | F24: =Inputs!$D$14*Inputs!$D$65*(1+Inputs!$D$70)^(F4-1) | G24: =Inputs!$D$14*Inputs!$D$65*(1+Inputs!$D$70)^(G4-1) | H24: =Inputs!$D$14*Inputs!$D$65*(1+Inputs!$D$70)^(H4-1) | I24: =Inputs!$D$14*Inputs!$D$65*(1+Inputs!$D$70)^(I4-1) | J24: =Inputs!$D$14*Inputs!$D$65*(1+Inputs!$D$70)^(J4-1) | ... BJ24: =Inputs!$D$14*Inputs!$D$65*(1+Inputs!$D$70)^(BJ4-1)
A25: Other fixed + land tax | C25: =Inputs!$D$64*(1+Inputs!$D$70)^(C4-1)+Inputs!$D$66/12 | D25: =Inputs!$D$64*(1+Inputs!$D$70)^(D4-1)+Inputs!$D$66/12 | E25: =Inputs!$D$64*(1+Inputs!$D$70)^(E4-1)+Inputs!$D$66/12 | F25: =Inputs!$D$64*(1+Inputs!$D$70)^(F4-1)+Inputs!$D$66/12 | G25: =Inputs!$D$64*(1+Inputs!$D$70)^(G4-1)+Inputs!$D$66/12 | H25: =Inputs!$D$64*(1+Inputs!$D$70)^(H4-1)+Inputs!$D$66/12 | I25: =Inputs!$D$64*(1+Inputs!$D$70)^(I4-1)+Inputs!$D$66/12 | J25: =Inputs!$D$64*(1+Inputs!$D$70)^(J4-1)+Inputs!$D$66/12 | ... BJ25: =Inputs!$D$64*(1+Inputs!$D$70)^(BJ4-1)+Inputs!$D$66/12
A26: Total operating costs | C26: =SUM(C15:C20)+C23+C24+C25 | D26: =SUM(D15:D20)+D23+D24+D25 | E26: =SUM(E15:E20)+E23+E24+E25 | F26: =SUM(F15:F20)+F23+F24+F25 | G26: =SUM(G15:G20)+G23+G24+G25 | H26: =SUM(H15:H20)+H23+H24+H25 | I26: =SUM(I15:I20)+I23+I24+I25 | J26: =SUM(J15:J20)+J23+J24+J25 | ... BJ26: =SUM(BJ15:BJ20)+BJ23+BJ24+BJ25
A27: EBITDA | C27: =C14-C26 | D27: =D14-D26 | E27: =E14-E26 | F27: =F14-F26 | G27: =G14-G26 | H27: =H14-H26 | I27: =I14-I26 | J27: =J14-J26 | ... BJ27: =BJ14-BJ26
A28: Depreciation | C28: =IF(AND(Inputs!$E$84>0,C3<=Inputs!$E$84*12),INDEX(Capex!$C$19:$E$19,1,Inputs!$E$13)/MAX(Inputs!$E$84,1)/12,0)+IF(AND(Inputs!$E$85>0,C3<=Inputs!$E$85*12),INDEX(Capex!$C$20:$E$20,1,Inputs!$E$13)/MAX(Inputs!$E$85,1)/12,0)+IF(AND(Inputs!$E$86>0,C3<=Inputs!$E$86*12),INDEX(Capex!$C$21:$E$21,1,Inputs!$E$13)/MAX(Inputs!$E$86,1)/12,0)+IF(AND(Inputs!$E$87>0,C3<=Inputs!$E$87*12),INDEX(Capex!$C$22:$E$22,1,Inputs!$E$13)/MAX(Inputs!$E$87,1)/12,0)+IF(AND(Inputs!$E$88>0,C3<=Inputs!$E$88*12),INDEX(Capex!$C$23:$E$23,1,Inputs!$E$13)/MAX(Inputs!$E$88,1)/12,0)+IF(AND(Inputs!$E$89>0,C3<=Inputs!$E$89*12),INDEX(Capex!$C$24:$E$24,1,Inputs!$E$13)/MAX(Inputs!$E$89,1)/12,0)+IF(AND(Inputs!$E$90>0,C3<=Inputs!$E$90*12),INDEX(Capex!$C$25:$E$25,1,Inputs!$E$13)/MAX(Inputs!$E$90,1)/12,0) | D28: =IF(AND(Inputs!$E$84>0,D3<=Inputs!$E$84*12),INDEX(Capex!$C$19:$E$19,1,Inputs!$E$13)/MAX(Inputs!$E$84,1)/12,0)+IF(AND(Inputs!$E$85>0,D3<=Inputs!$E$85*12),INDEX(Capex!$C$20:$E$20,1,Inputs!$E$13)/MAX(Inputs!$E$85,1)/12,0)+IF(AND(Inputs!$E$86>0,D3<=Inputs!$E$86*12),INDEX(Capex!$C$21:$E$21,1,Inputs!$E$13)/MAX(Inputs!$E$86,1)/12,0)+IF(AND(Inputs!$E$87>0,D3<=Inputs!$E$87*12),INDEX(Capex!$C$22:$E$22,1,Inputs!$E$13)/MAX(Inputs!$E$87,1)/12,0)+IF(AND(Inputs!$E$88>0,D3<=Inputs!$E$88*12),INDEX(Capex!$C$23:$E$23,1,Inputs!$E$13)/MAX(Inputs!$E$88,1)/12,0)+IF(AND(Inputs!$E$89>0,D3<=Inputs!$E$89*12),INDEX(Capex!$C$24:$E$24,1,Inputs!$E$13)/MAX(Inputs!$E$89,1)/12,0)+IF(AND(Inputs!$E$90>0,D3<=Inputs!$E$90*12),INDEX(Capex!$C$25:$E$25,1,Inputs!$E$13)/MAX(Inputs!$E$90,1)/12,0) | E28: =IF(AND(Inputs!$E$84>0,E3<=Inputs!$E$84*12),INDEX(Capex!$C$19:$E$19,1,Inputs!$E$13)/MAX(Inputs!$E$84,1)/12,0)+IF(AND(Inputs!$E$85>0,E3<=Inputs!$E$85*12),INDEX(Capex!$C$20:$E$20,1,Inputs!$E$13)/MAX(Inputs!$E$85,1)/12,0)+IF(AND(Inputs!$E$86>0,E3<=Inputs!$E$86*12),INDEX(Capex!$C$21:$E$21,1,Inputs!$E$13)/MAX(Inputs!$E$86,1)/12,0)+IF(AND(Inputs!$E$87>0,E3<=Inputs!$E$87*12),INDEX(Capex!$C$22:$E$22,1,Inputs!$E$13)/MAX(Inputs!$E$87,1)/12,0)+IF(AND(Inputs!$E$88>0,E3<=Inputs!$E$88*12),INDEX(Capex!$C$23:$E$23,1,Inputs!$E$13)/MAX(Inputs!$E$88,1)/12,0)+IF(AND(Inputs!$E$89>0,E3<=Inputs!$E$89*12),INDEX(Capex!$C$24:$E$24,1,Inputs!$E$13)/MAX(Inputs!$E$89,1)/12,0)+IF(AND(Inputs!$E$90>0,E3<=Inputs!$E$90*12),INDEX(Capex!$C$25:$E$25,1,Inputs!$E$13)/MAX(Inputs!$E$90,1)/12,0) | F28: =IF(AND(Inputs!$E$84>0,F3<=Inputs!$E$84*12),INDEX(Capex!$C$19:$E$19,1,Inputs!$E$13)/MAX(Inputs!$E$84,1)/12,0)+IF(AND(Inputs!$E$85>0,F3<=Inputs!$E$85*12),INDEX(Capex!$C$20:$E$20,1,Inputs!$E$13)/MAX(Inputs!$E$85,1)/12,0)+IF(AND(Inputs!$E$86>0,F3<=Inputs!$E$86*12),INDEX(Capex!$C$21:$E$21,1,Inputs!$E$13)/MAX(Inputs!$E$86,1)/12,0)+IF(AND(Inputs!$E$87>0,F3<=Inputs!$E$87*12),INDEX(Capex!$C$22:$E$22,1,Inputs!$E$13)/MAX(Inputs!$E$87,1)/12,0)+IF(AND(Inputs!$E$88>0,F3<=Inputs!$E$88*12),INDEX(Capex!$C$23:$E$23,1,Inputs!$E$13)/MAX(Inputs!$E$88,1)/12,0)+IF(AND(Inputs!$E$89>0,F3<=Inputs!$E$89*12),INDEX(Capex!$C$24:$E$24,1,Inputs!$E$13)/MAX(Inputs!$E$89,1)/12,0)+IF(AND(Inputs!$E$90>0,F3<=Inputs!$E$90*12),INDEX(Capex!$C$25:$E$25,1,Inputs!$E$13)/MAX(Inputs!$E$90,1)/12,0) | G28: =IF(AND(Inputs!$E$84>0,G3<=Inputs!$E$84*12),INDEX(Capex!$C$19:$E$19,1,Inputs!$E$13)/MAX(Inputs!$E$84,1)/12,0)+IF(AND(Inputs!$E$85>0,G3<=Inputs!$E$85*12),INDEX(Capex!$C$20:$E$20,1,Inputs!$E$13)/MAX(Inputs!$E$85,1)/12,0)+IF(AND(Inputs!$E$86>0,G3<=Inputs!$E$86*12),INDEX(Capex!$C$21:$E$21,1,Inputs!$E$13)/MAX(Inputs!$E$86,1)/12,0)+IF(AND(Inputs!$E$87>0,G3<=Inputs!$E$87*12),INDEX(Capex!$C$22:$E$22,1,Inputs!$E$13)/MAX(Inputs!$E$87,1)/12,0)+IF(AND(Inputs!$E$88>0,G3<=Inputs!$E$88*12),INDEX(Capex!$C$23:$E$23,1,Inputs!$E$13)/MAX(Inputs!$E$88,1)/12,0)+IF(AND(Inputs!$E$89>0,G3<=Inputs!$E$89*12),INDEX(Capex!$C$24:$E$24,1,Inputs!$E$13)/MAX(Inputs!$E$89,1)/12,0)+IF(AND(Inputs!$E$90>0,G3<=Inputs!$E$90*12),INDEX(Capex!$C$25:$E$25,1,Inputs!$E$13)/MAX(Inputs!$E$90,1)/12,0) | H28: =IF(AND(Inputs!$E$84>0,H3<=Inputs!$E$84*12),INDEX(Capex!$C$19:$E$19,1,Inputs!$E$13)/MAX(Inputs!$E$84,1)/12,0)+IF(AND(Inputs!$E$85>0,H3<=Inputs!$E$85*12),INDEX(Capex!$C$20:$E$20,1,Inputs!$E$13)/MAX(Inputs!$E$85,1)/12,0)+IF(AND(Inputs!$E$86>0,H3<=Inputs!$E$86*12),INDEX(Capex!$C$21:$E$21,1,Inputs!$E$13)/MAX(Inputs!$E$86,1)/12,0)+IF(AND(Inputs!$E$87>0,H3<=Inputs!$E$87*12),INDEX(Capex!$C$22:$E$22,1,Inputs!$E$13)/MAX(Inputs!$E$87,1)/12,0)+IF(AND(Inputs!$E$88>0,H3<=Inputs!$E$88*12),INDEX(Capex!$C$23:$E$23,1,Inputs!$E$13)/MAX(Inputs!$E$88,1)/12,0)+IF(AND(Inputs!$E$89>0,H3<=Inputs!$E$89*12),INDEX(Capex!$C$24:$E$24,1,Inputs!$E$13)/MAX(Inputs!$E$89,1)/12,0)+IF(AND(Inputs!$E$90>0,H3<=Inputs!$E$90*12),INDEX(Capex!$C$25:$E$25,1,Inputs!$E$13)/MAX(Inputs!$E$90,1)/12,0) | I28: =IF(AND(Inputs!$E$84>0,I3<=Inputs!$E$84*12),INDEX(Capex!$C$19:$E$19,1,Inputs!$E$13)/MAX(Inputs!$E$84,1)/12,0)+IF(AND(Inputs!$E$85>0,I3<=Inputs!$E$85*12),INDEX(Capex!$C$20:$E$20,1,Inputs!$E$13)/MAX(Inputs!$E$85,1)/12,0)+IF(AND(Inputs!$E$86>0,I3<=Inputs!$E$86*12),INDEX(Capex!$C$21:$E$21,1,Inputs!$E$13)/MAX(Inputs!$E$86,1)/12,0)+IF(AND(Inputs!$E$87>0,I3<=Inputs!$E$87*12),INDEX(Capex!$C$22:$E$22,1,Inputs!$E$13)/MAX(Inputs!$E$87,1)/12,0)+IF(AND(Inputs!$E$88>0,I3<=Inputs!$E$88*12),INDEX(Capex!$C$23:$E$23,1,Inputs!$E$13)/MAX(Inputs!$E$88,1)/12,0)+IF(AND(Inputs!$E$89>0,I3<=Inputs!$E$89*12),INDEX(Capex!$C$24:$E$24,1,Inputs!$E$13)/MAX(Inputs!$E$89,1)/12,0)+IF(AND(Inputs!$E$90>0,I3<=Inputs!$E$90*12),INDEX(Capex!$C$25:$E$25,1,Inputs!$E$13)/MAX(Inputs!$E$90,1)/12,0) | J28: =IF(AND(Inputs!$E$84>0,J3<=Inputs!$E$84*12),INDEX(Capex!$C$19:$E$19,1,Inputs!$E$13)/MAX(Inputs!$E$84,1)/12,0)+IF(AND(Inputs!$E$85>0,J3<=Inputs!$E$85*12),INDEX(Capex!$C$20:$E$20,1,Inputs!$E$13)/MAX(Inputs!$E$85,1)/12,0)+IF(AND(Inputs!$E$86>0,J3<=Inputs!$E$86*12),INDEX(Capex!$C$21:$E$21,1,Inputs!$E$13)/MAX(Inputs!$E$86,1)/12,0)+IF(AND(Inputs!$E$87>0,J3<=Inputs!$E$87*12),INDEX(Capex!$C$22:$E$22,1,Inputs!$E$13)/MAX(Inputs!$E$87,1)/12,0)+IF(AND(Inputs!$E$88>0,J3<=Inputs!$E$88*12),INDEX(Capex!$C$23:$E$23,1,Inputs!$E$13)/MAX(Inputs!$E$88,1)/12,0)+IF(AND(Inputs!$E$89>0,J3<=Inputs!$E$89*12),INDEX(Capex!$C$24:$E$24,1,Inputs!$E$13)/MAX(Inputs!$E$89,1)/12,0)+IF(AND(Inputs!$E$90>0,J3<=Inputs!$E$90*12),INDEX(Capex!$C$25:$E$25,1,Inputs!$E$13)/MAX(Inputs!$E$90,1)/12,0) | ... BJ28: =IF(AND(Inputs!$E$84>0,BJ3<=Inputs!$E$84*12),INDEX(Capex!$C$19:$E$19,1,Inputs!$E$13)/MAX(Inputs!$E$84,1)/12,0)+IF(AND(Inputs!$E$85>0,BJ3<=Inputs!$E$85*12),INDEX(Capex!$C$20:$E$20,1,Inputs!$E$13)/MAX(Inputs!$E$85,1)/12,0)+IF(AND(Inputs!$E$86>0,BJ3<=Inputs!$E$86*12),INDEX(Capex!$C$21:$E$21,1,Inputs!$E$13)/MAX(Inputs!$E$86,1)/12,0)+IF(AND(Inputs!$E$87>0,BJ3<=Inputs!$E$87*12),INDEX(Capex!$C$22:$E$22,1,Inputs!$E$13)/MAX(Inputs!$E$87,1)/12,0)+IF(AND(Inputs!$E$88>0,BJ3<=Inputs!$E$88*12),INDEX(Capex!$C$23:$E$23,1,Inputs!$E$13)/MAX(Inputs!$E$88,1)/12,0)+IF(AND(Inputs!$E$89>0,BJ3<=Inputs!$E$89*12),INDEX(Capex!$C$24:$E$24,1,Inputs!$E$13)/MAX(Inputs!$E$89,1)/12,0)+IF(AND(Inputs!$E$90>0,BJ3<=Inputs!$E$90*12),INDEX(Capex!$C$25:$E$25,1,Inputs!$E$13)/MAX(Inputs!$E$90,1)/12,0)
A29: EBIT | C29: =C27-C28 | D29: =D27-D28 | E29: =E27-E28 | F29: =F27-F28 | G29: =G27-G28 | H29: =H27-H28 | I29: =I27-I28 | J29: =J27-J28 | ... BJ29: =BJ27-BJ28
A30: Cash before tax/capex adj. | C30: =C27-(INDEX(Annual!$C$27:$G$27,1,C4)+INDEX(Annual!$C$30:$G$30,1,C4)+INDEX(Annual!$C$32:$G$32,1,C4))/12 | D30: =D27-(INDEX(Annual!$C$27:$G$27,1,D4)+INDEX(Annual!$C$30:$G$30,1,D4)+INDEX(Annual!$C$32:$G$32,1,D4))/12 | E30: =E27-(INDEX(Annual!$C$27:$G$27,1,E4)+INDEX(Annual!$C$30:$G$30,1,E4)+INDEX(Annual!$C$32:$G$32,1,E4))/12 | F30: =F27-(INDEX(Annual!$C$27:$G$27,1,F4)+INDEX(Annual!$C$30:$G$30,1,F4)+INDEX(Annual!$C$32:$G$32,1,F4))/12 | G30: =G27-(INDEX(Annual!$C$27:$G$27,1,G4)+INDEX(Annual!$C$30:$G$30,1,G4)+INDEX(Annual!$C$32:$G$32,1,G4))/12 | H30: =H27-(INDEX(Annual!$C$27:$G$27,1,H4)+INDEX(Annual!$C$30:$G$30,1,H4)+INDEX(Annual!$C$32:$G$32,1,H4))/12 | I30: =I27-(INDEX(Annual!$C$27:$G$27,1,I4)+INDEX(Annual!$C$30:$G$30,1,I4)+INDEX(Annual!$C$32:$G$32,1,I4))/12 | J30: =J27-(INDEX(Annual!$C$27:$G$27,1,J4)+INDEX(Annual!$C$30:$G$30,1,J4)+INDEX(Annual!$C$32:$G$32,1,J4))/12 | ... BJ30: =BJ27-(INDEX(Annual!$C$27:$G$27,1,BJ4)+INDEX(Annual!$C$30:$G$30,1,BJ4)+INDEX(Annual!$C$32:$G$32,1,BJ4))/12
A31: Cumulative cash (after investment) | C31: =-INDEX(Capex!$C$15:$E$15,1,Inputs!$E$13)+C30 | D31: =C31+D30 | E31: =D31+E30 | F31: =E31+F30 | G31: =F31+G30 | H31: =G31+H30 | I31: =H31+I30 | J31: =I31+J30 | K31: =J31+K30 | ... BJ31: =BI31+BJ30
A32: Payback flag | C32: =IF(C31>=0,C3,999) | D32: =IF(D31>=0,D3,999) | E32: =IF(E31>=0,E3,999) | F32: =IF(F31>=0,F3,999) | G32: =IF(G31>=0,G3,999) | H32: =IF(H31>=0,H3,999) | I32: =IF(I31>=0,I3,999) | J32: =IF(J31>=0,J3,999) | ... BJ32: =IF(BJ31>=0,BJ3,999)

Sheet M_Base
A1: Drive-thru — monthly engine — BASE scenario (AMD)
B2: Units | C2: =CHOOSE(C5,"Jan","Feb","Mar","Apr","May","Jun","Jul","Aug","Sep","Oct","Nov","Dec")&" Y"&C4 | D2: =CHOOSE(D5,"Jan","Feb","Mar","Apr","May","Jun","Jul","Aug","Sep","Oct","Nov","Dec")&" Y"&D4 | E2: =CHOOSE(E5,"Jan","Feb","Mar","Apr","May","Jun","Jul","Aug","Sep","Oct","Nov","Dec")&" Y"&E4 | F2: =CHOOSE(F5,"Jan","Feb","Mar","Apr","May","Jun","Jul","Aug","Sep","Oct","Nov","Dec")&" Y"&F4 | G2: =CHOOSE(G5,"Jan","Feb","Mar","Apr","May","Jun","Jul","Aug","Sep","Oct","Nov","Dec")&" Y"&G4 | H2: =CHOOSE(H5,"Jan","Feb","Mar","Apr","May","Jun","Jul","Aug","Sep","Oct","Nov","Dec")&" Y"&H4 | I2: =CHOOSE(I5,"Jan","Feb","Mar","Apr","May","Jun","Jul","Aug","Sep","Oct","Nov","Dec")&" Y"&I4 | J2: =CHOOSE(J5,"Jan","Feb","Mar","Apr","May","Jun","Jul","Aug","Sep","Oct","Nov","Dec")&" Y"&J4 | ... BJ2: =CHOOSE(BJ5,"Jan","Feb","Mar","Apr","May","Jun","Jul","Aug","Sep","Oct","Nov","Dec")&" Y"&BJ4
A3: Month # | C3: 1 | D3: 2 | E3: 3 | F3: 4 | G3: 5 | H3: 6 | I3: 7 | J3: 8 | K3: 9 | L3: 10 | M3: 11 | N3: 12 | O3: 13 | P3: 14 | Q3: 15 | R3: 16 | S3: 17 | T3: 18 | U3: 19 | V3: 20 | W3: 21 | X3: 22 | Y3: 23 | Z3: 24 | AA3: 25 | AB3: 26 | AC3: 27 | AD3: 28 | AE3: 29 | AF3: 30 | AG3: 31 | AH3: 32 | AI3: 33 | AJ3: 34 | AK3: 35 | AL3: 36 | AM3: 37 | AN3: 38 | AO3: 39 | AP3: 40 | AQ3: 41 | AR3: 42 | AS3: 43 | AT3: 44 | AU3: 45 | AV3: 46 | AW3: 47 | AX3: 48 | AY3: 49 | AZ3: 50 | BA3: 51 | BB3: 52 | BC3: 53 | BD3: 54 | BE3: 55 | BF3: 56 | BG3: 57 | BH3: 58 | BI3: 59 | BJ3: 60
A4: Year | C4: =INT((C3-1)/12)+1 | D4: =INT((D3-1)/12)+1 | E4: =INT((E3-1)/12)+1 | F4: =INT((F3-1)/12)+1 | G4: =INT((G3-1)/12)+1 | H4: =INT((H3-1)/12)+1 | I4: =INT((I3-1)/12)+1 | J4: =INT((J3-1)/12)+1 | ... BJ4: =INT((BJ3-1)/12)+1
A5: Calendar month (1-12) | C5: =MOD(Inputs!$E$8-1+C3-1,12)+1 | D5: =MOD(Inputs!$E$8-1+D3-1,12)+1 | E5: =MOD(Inputs!$E$8-1+E3-1,12)+1 | F5: =MOD(Inputs!$E$8-1+F3-1,12)+1 | G5: =MOD(Inputs!$E$8-1+G3-1,12)+1 | H5: =MOD(Inputs!$E$8-1+H3-1,12)+1 | I5: =MOD(Inputs!$E$8-1+I3-1,12)+1 | J5: =MOD(Inputs!$E$8-1+J3-1,12)+1 | ... BJ5: =MOD(Inputs!$E$8-1+BJ3-1,12)+1
A6: Trading days | C6: =CHOOSE(C5,31,28,31,30,31,30,31,31,30,31,30,31)*Inputs!$E$9/365 | D6: =CHOOSE(D5,31,28,31,30,31,30,31,31,30,31,30,31)*Inputs!$E$9/365 | E6: =CHOOSE(E5,31,28,31,30,31,30,31,31,30,31,30,31)*Inputs!$E$9/365 | F6: =CHOOSE(F5,31,28,31,30,31,30,31,31,30,31,30,31)*Inputs!$E$9/365 | G6: =CHOOSE(G5,31,28,31,30,31,30,31,31,30,31,30,31)*Inputs!$E$9/365 | H6: =CHOOSE(H5,31,28,31,30,31,30,31,31,30,31,30,31)*Inputs!$E$9/365 | I6: =CHOOSE(I5,31,28,31,30,31,30,31,31,30,31,30,31)*Inputs!$E$9/365 | J6: =CHOOSE(J5,31,28,31,30,31,30,31,31,30,31,30,31)*Inputs!$E$9/365 | ... BJ6: =CHOOSE(BJ5,31,28,31,30,31,30,31,31,30,31,30,31)*Inputs!$E$9/365
A7: Seasonality index | C7: =INDEX(Inputs!$E$27:$E$38,C5) | D7: =INDEX(Inputs!$E$27:$E$38,D5) | E7: =INDEX(Inputs!$E$27:$E$38,E5) | F7: =INDEX(Inputs!$E$27:$E$38,F5) | G7: =INDEX(Inputs!$E$27:$E$38,G5) | H7: =INDEX(Inputs!$E$27:$E$38,H5) | I7: =INDEX(Inputs!$E$27:$E$38,I5) | J7: =INDEX(Inputs!$E$27:$E$38,J5) | ... BJ7: =INDEX(Inputs!$E$27:$E$38,BJ5)
A8: Passing traffic (veh/day) | C8: =Inputs!$E$17*(1+Inputs!$E$18)^(C4-1)*C7 | D8: =Inputs!$E$17*(1+Inputs!$E$18)^(D4-1)*D7 | E8: =Inputs!$E$17*(1+Inputs!$E$18)^(E4-1)*E7 | F8: =Inputs!$E$17*(1+Inputs!$E$18)^(F4-1)*F7 | G8: =Inputs!$E$17*(1+Inputs!$E$18)^(G4-1)*G7 | H8: =Inputs!$E$17*(1+Inputs!$E$18)^(H4-1)*H7 | I8: =Inputs!$E$17*(1+Inputs!$E$18)^(I4-1)*I7 | J8: =Inputs!$E$17*(1+Inputs!$E$18)^(J4-1)*J7 | ... BJ8: =Inputs!$E$17*(1+Inputs!$E$18)^(BJ4-1)*BJ7
A9: Ramp multiplier | C9: =IF(C3<=12,INDEX(Inputs!$E$41:$E$52,C3),1) | D9: =IF(D3<=12,INDEX(Inputs!$E$41:$E$52,D3),1) | E9: =IF(E3<=12,INDEX(Inputs!$E$41:$E$52,E3),1) | F9: =IF(F3<=12,INDEX(Inputs!$E$41:$E$52,F3),1) | G9: =IF(G3<=12,INDEX(Inputs!$E$41:$E$52,G3),1) | H9: =IF(H3<=12,INDEX(Inputs!$E$41:$E$52,H3),1) | I9: =IF(I3<=12,INDEX(Inputs!$E$41:$E$52,I3),1) | J9: =IF(J3<=12,INDEX(Inputs!$E$41:$E$52,J3),1) | ... BJ9: =IF(BJ3<=12,INDEX(Inputs!$E$41:$E$52,BJ3),1)
A10: Capture rate | C10: =Inputs!$E$20*(1+Inputs!$E$21)^(C4-1)*C9 | D10: =Inputs!$E$20*(1+Inputs!$E$21)^(D4-1)*D9 | E10: =Inputs!$E$20*(1+Inputs!$E$21)^(E4-1)*E9 | F10: =Inputs!$E$20*(1+Inputs!$E$21)^(F4-1)*F9 | G10: =Inputs!$E$20*(1+Inputs!$E$21)^(G4-1)*G9 | H10: =Inputs!$E$20*(1+Inputs!$E$21)^(H4-1)*H9 | I10: =Inputs!$E$20*(1+Inputs!$E$21)^(I4-1)*I9 | J10: =Inputs!$E$20*(1+Inputs!$E$21)^(J4-1)*J9 | ... BJ10: =Inputs!$E$20*(1+Inputs!$E$21)^(BJ4-1)*BJ9
A11: Transactions / day | C11: =C8*Inputs!$E$19*C10+Inputs!$E$23*C9 | D11: =D8*Inputs!$E$19*D10+Inputs!$E$23*D9 | E11: =E8*Inputs!$E$19*E10+Inputs!$E$23*E9 | F11: =F8*Inputs!$E$19*F10+Inputs!$E$23*F9 | G11: =G8*Inputs!$E$19*G10+Inputs!$E$23*G9 | H11: =H8*Inputs!$E$19*H10+Inputs!$E$23*H9 | I11: =I8*Inputs!$E$19*I10+Inputs!$E$23*I9 | J11: =J8*Inputs!$E$19*J10+Inputs!$E$23*J9 | ... BJ11: =BJ8*Inputs!$E$19*BJ10+Inputs!$E$23*BJ9
A12: Average ticket (AMD, incl. VAT) | C12: =Inputs!$E$22*(1+Inputs!$E$24)^(C4-1) | D12: =Inputs!$E$22*(1+Inputs!$E$24)^(D4-1) | E12: =Inputs!$E$22*(1+Inputs!$E$24)^(E4-1) | F12: =Inputs!$E$22*(1+Inputs!$E$24)^(F4-1) | G12: =Inputs!$E$22*(1+Inputs!$E$24)^(G4-1) | H12: =Inputs!$E$22*(1+Inputs!$E$24)^(H4-1) | I12: =Inputs!$E$22*(1+Inputs!$E$24)^(I4-1) | J12: =Inputs!$E$22*(1+Inputs!$E$24)^(J4-1) | ... BJ12: =Inputs!$E$22*(1+Inputs!$E$24)^(BJ4-1)
A13: Gross sales (incl. VAT) | C13: =C11*C6*C12 | D13: =D11*D6*D12 | E13: =E11*E6*E12 | F13: =F11*F6*F12 | G13: =G11*G6*G12 | H13: =H11*H6*H12 | I13: =I11*I6*I12 | J13: =J11*J6*J12 | ... BJ13: =BJ11*BJ6*BJ12
A14: Net sales (excl. VAT) | C14: =C13/(1+Inputs!$E$10) | D14: =D13/(1+Inputs!$E$10) | E14: =E13/(1+Inputs!$E$10) | F14: =F13/(1+Inputs!$E$10) | G14: =G13/(1+Inputs!$E$10) | H14: =H13/(1+Inputs!$E$10) | I14: =I13/(1+Inputs!$E$10) | J14: =J13/(1+Inputs!$E$10) | ... BJ14: =BJ13/(1+Inputs!$E$10)
A15: COGS + waste | C15: =C14*(Inputs!$E$55+Inputs!$E$56) | D15: =D14*(Inputs!$E$55+Inputs!$E$56) | E15: =E14*(Inputs!$E$55+Inputs!$E$56) | F15: =F14*(Inputs!$E$55+Inputs!$E$56) | G15: =G14*(Inputs!$E$55+Inputs!$E$56) | H15: =H14*(Inputs!$E$55+Inputs!$E$56) | I15: =I14*(Inputs!$E$55+Inputs!$E$56) | J15: =J14*(Inputs!$E$55+Inputs!$E$56) | ... BJ15: =BJ14*(Inputs!$E$55+Inputs!$E$56)
